<mujoco model="example_scene_3.xml">
	<include file="/home/szabo/github/AIMotionLab-Virtual/aiml_virtual/resources/xml_models/scene_base_with_static_objects.xml" />
	<worldbody>
		<body name="Crazyflie_0" pos="-0.5 -1 1" quat="1 0 0 0">
			<geom name="Crazyflie_0_body" type="mesh" mesh="crazyflie_body" rgba="0.5 0.5 0.5 1" />
			<geom name="Crazyflie_0_4_motormounts" type="mesh" mesh="crazyflie_4_motormounts" rgba="0.5 0.5 0.5 1" />
			<geom name="Crazyflie_0_4_motors" type="mesh" mesh="crazyflie_4_motors" rgba="0.5 0.5 0.5 1" />
			<inertial pos="0.0 0.0 0.0" diaginertia="1.4e-5 1.4e-5 2.17e-5" mass="0.028" />
			<joint name="Crazyflie_0" type="free" />
			<site name="Crazyflie_0_cog" pos="0 0 0" size="0.005" rgba="0.5 0.5 0.5 0.0" />
			<body name="Crazyflie_0_prop0">
				<joint name="Crazyflie_0_prop0" axis="0 0 1" pos="0.03275 -0.03275 0.0223" />
				<geom name="Crazyflie_0_prop0" type="mesh" mesh="crazyflie_ccw_prop" mass="0.00001" pos="0.03275 -0.03275 0.0223" rgba="0.1 0.1 0.1 1.0" />
			</body>
			<site name="Crazyflie_0_prop0" pos="0.03275 -0.03275 0.0223" size="0.0001" />
			<body name="Crazyflie_0_prop1">
				<joint name="Crazyflie_0_prop1" axis="0 0 1" pos="-0.03275 -0.03275 0.0223" />
				<geom name="Crazyflie_0_prop1" type="mesh" mesh="crazyflie_cw_prop" mass="0.00001" pos="-0.03275 -0.03275 0.0223" rgba="0.1 0.1 0.1 1.0" />
			</body>
			<site name="Crazyflie_0_prop1" pos="-0.03275 -0.03275 0.0223" size="0.0001" />
			<body name="Crazyflie_0_prop2">
				<joint name="Crazyflie_0_prop2" axis="0 0 1" pos="-0.03275 0.03275 0.0223" />
				<geom name="Crazyflie_0_prop2" type="mesh" mesh="crazyflie_ccw_prop" mass="0.00001" pos="-0.03275 0.03275 0.0223" rgba="0.1 0.1 0.1 1.0" />
			</body>
			<site name="Crazyflie_0_prop2" pos="-0.03275 0.03275 0.0223" size="0.0001" />
			<body name="Crazyflie_0_prop3">
				<joint name="Crazyflie_0_prop3" axis="0 0 1" pos="0.03275 0.03275 0.0223" />
				<geom name="Crazyflie_0_prop3" type="mesh" mesh="crazyflie_cw_prop" mass="0.00001" pos="0.03275 0.03275 0.0223" rgba="0.1 0.1 0.1 1.0" />
			</body>
			<site name="Crazyflie_0_prop3" pos="0.03275 0.03275 0.0223" size="0.0001" />
		</body>
	</worldbody>
	<actuator>
		<general site="Crazyflie_0_prop0" name="Crazyflie_0_actr0" gear="0 0 1 0 0 0.02514" ctrllimited="true" ctrlrange="0 0.16" />
		<general site="Crazyflie_0_prop1" name="Crazyflie_0_actr1" gear="0 0 1 0 0 -0.02514" ctrllimited="true" ctrlrange="0 0.16" />
		<general site="Crazyflie_0_prop2" name="Crazyflie_0_actr2" gear="0 0 1 0 0 0.02514" ctrllimited="true" ctrlrange="0 0.16" />
		<general site="Crazyflie_0_prop3" name="Crazyflie_0_actr3" gear="0 0 1 0 0 -0.02514" ctrllimited="true" ctrlrange="0 0.16" />
	</actuator>
	<sensor>
		<gyro site="Crazyflie_0_cog" name="Crazyflie_0_gyro" />
		<framelinvel objtype="site" objname="Crazyflie_0_cog" name="Crazyflie_0_velocimeter" />
		<accelerometer site="Crazyflie_0_cog" name="Crazyflie_0_accelerometer" />
		<framepos objtype="site" objname="Crazyflie_0_cog" name="Crazyflie_0_posimeter" />
		<framequat objtype="site" objname="Crazyflie_0_cog" name="Crazyflie_0_orimeter" />
		<frameangacc objtype="site" objname="Crazyflie_0_cog" name="Crazyflie_0_ang_accelerometer" />
	</sensor>
</mujoco>