<mujoco model="empty_checkerboard">
	<include file="common_assets.xml" />
	<default class="main">
		<default class="pole">
			<geom rgba="0.1 0.1 0.1 1" />
			<default class="pole_top">
				<geom type="cylinder" size="0.022 0.5" pos="0 0 0.5" />
			</default>
			<default class="pole_bottom1">
				<geom type="box" size="0.02 0.205 0.02" quat="0.7071 0 0 0.7071" pos="0 0 0.02" />
				<default class="pole_bottom2">
					<geom quat="1 0 0 0" />
				</default>
			</default>
		</default>
		<default class="landing_zone">
			<geom type="box" pos="0 0 0.01" size="0.1175 0.0975 0.01" rgba="0.8 0.8 0.8 1.0" />
		</default>
	</default>
	<compiler angle="radian" meshdir="" />
	<option timestep="0.001" integrator="implicitfast" />
	<visual>
		<quality shadowsize="4096" />
		<global offwidth="1920" offheight="1200" />
	</visual>
	<asset>
		<mesh file="meshes/crazyflie/cf2_assembly.stl" name="crazyflie" smoothnormal="true" scale="1.5 1.5 1.5" />
		<mesh file="meshes/building/lagyi_cockpit.stl" name="cockpit" smoothnormal="true" scale="0.0085 0.0085 0.0085" />
		<mesh file="meshes/building/lagyi_fal1.stl" name="fal1" smoothnormal="true" scale="0.0085 0.0085 0.0085" />
		<mesh file="meshes/building/lagyi_fal2.stl" name="fal2" smoothnormal="true" scale="0.0085 0.0085 0.0085" />
		<mesh file="meshes/building/lagyi_oszlop1.stl" name="oszlop1" smoothnormal="true" scale="0.0085 0.0085 0.0085" />
		<mesh file="meshes/building/lagyi_oszlop2.stl" name="oszlop2" smoothnormal="true" scale="0.0085 0.0085 0.0085" />
		<mesh file="meshes/building/lagyi_oszlop3.stl" name="oszlop3" smoothnormal="true" scale="0.0085 0.0085 0.0085" />
		<mesh file="meshes/building/lagyi_oszlop4.stl" name="oszlop4" smoothnormal="true" scale="0.0085 0.0085 0.0085" />
		<mesh file="meshes/bucket/Bucket3.obj" name="bucket" smoothnormal="false" scale="0.035 0.035 0.035" />
		<texture type="skybox" builtin="gradient" rgb1=".3 .5 .7" rgb2="0 0 0" width="512" height="512" />
		<texture name="tex-carpet" type="2d" file="textures/carpet_lagyi4.png" />
		<texture name="tex-roundabout" type="2d" file="textures/roundabout.png" />
		<texture name="tex-hospital" type="2d" file="textures/hospital.png" />
		<texture name="tex-post_office" type="2d" file="textures/post_office.png" />
		<texture name="tex-airport" type="2d" file="textures/airport.png" />
		<texture name="tex-parking_lot" type="2d" file="textures/parking_lot.png" />
		<texture name="tex-sztaki" type="2d" file="textures/sztaki.png" />
		<material name="mat-carpet" shininess="0.1" texture="tex-carpet" texuniform="false" />
		<material name="mat-roundabout" reflectance="0.7" texture="tex-roundabout" texuniform="false" />
		<material name="mat-hospital" reflectance="0.7" texrepeat="7.843 7.692" texture="tex-hospital" texuniform="true" />
		<material name="mat-post_office" reflectance="0.7" texrepeat="7.843 7.843" texture="tex-post_office" texuniform="true" />
		<material name="mat-airport" reflectance="0.7" texrepeat="9.524 9.524" texture="tex-airport" texuniform="true" />
		<material name="mat-parking_lot" reflectance="0.7" texrepeat="9.524 8.696" texture="tex-parking_lot" texuniform="true" />
		<material name="mat-sztaki" reflectance="0.7" texrepeat="9.524 9.524" texture="tex-sztaki" texuniform="true" />
		<texture name="grid" type="2d" builtin="checker" width="100" height="100" rgb1=".1 .2 .3" rgb2=".25 .35 .45" />
		<material name="grid" texture="grid" texrepeat="1 1" texuniform="true" reflectance=".05" />
	</asset>
	<worldbody>
		<light dir="0 -0.3 -1" diffuse=".9 .9 .9" specular="0.6 0.9 0.6" pos="1 1 15" cutoff="70" />
		<light dir="-.2 1 -.4" diffuse=".9 .9 .9" specular="0.6 0.9 0.6" pos="2 -5 6" cutoff="70" />
		<light dir="-1.0 -1.0 -.4" diffuse=".9 .9 .9" specular="0.6 0.9 0.6" pos="10 10 6" directional="true" cutoff="70" />
		<camera pos="2.867 -5.173 1.776" xyaxes="0.875 0.485 0.000 -0.139 0.252 0.958" />
		<geom name="ground" size="20 20 .005" type="plane" material="grid" condim="3" />
		<body name="Bicycle_0" pos="0 1 0.1" quat="1 0 0 0">
			<inertial pos="0 0 0" diaginertia=".01 .01 .01" mass="1.0" />
			<joint name="Bicycle_0" type="free" />
			<site name="Bicycle_0_cog" pos="0 0 0" />
			<geom name="Bicycle_0_crossbar" type="box" size=".06 .015 .02" pos="0 0 0" rgba="0.5 0.5 0.5 1" />
			<body name="Bicycle_0_wheelf">
				<joint name="Bicycle_0_wheelf" type="hinge" pos="0.1 0 0" axis="0 1 0" frictionloss="0.001" damping="0.00001" armature="0.01" />
				<geom name="Bicycle_0_wheelf" type="cylinder" size="0.04 0.015" pos="0.1 0 0" euler="1.571 0 0" material="material_check" />
			</body>
			<body name="Bicycle_0_wheelr">
				<joint name="Bicycle_0_wheelr" type="hinge" pos="-0.1 0 0" axis="0 1 0" frictionloss="0.001" damping="0.00001" armature="0.01" />
				<geom name="Bicycle_0_wheelr" type="cylinder" size="0.04 0.015" pos="-0.1 0 0" euler="1.571 0 0" material="material_check" />
			</body>
		</body>
		<body name="HookedBumblebee1DOF_0" pos="-1 0 0.7" quat="1 0 0 0">
			<geom name="HookedBumblebee1DOF_0_body" pos="0.0132 0 0" type="mesh" quat="-0.7071067811865475 -0.0 0.0 0.7071067811865476" mesh="bumblebee_body" rgba="0.5 0.5 0.5 1" />
			<inertial pos="0.0085 0.0 0.0" diaginertia="1.5e-3 1.45e-3 2.66e-3" mass="0.605" />
			<joint name="HookedBumblebee1DOF_0" type="free" />
			<site name="HookedBumblebee1DOF_0_cog" pos="0 0 0" size="0.005" />
			<body name="HookedBumblebee1DOF_0_prop0">
				<joint name="HookedBumblebee1DOF_0_prop0" axis="0 0 1" pos="0.091 -0.087 0.036" />
				<geom name="HookedBumblebee1DOF_0_prop0" type="mesh" mesh="bumblebee_ccw_prop" mass="0.00001" pos="0.091 -0.087 0.036" rgba="0.1 0.02 0.5 1.0" />
			</body>
			<site name="HookedBumblebee1DOF_0_prop0" pos="0.091 -0.087 0.036" size="0.0001" />
			<body name="HookedBumblebee1DOF_0_prop1">
				<joint name="HookedBumblebee1DOF_0_prop1" axis="0 0 1" pos="-0.074 -0.087 0.036" />
				<geom name="HookedBumblebee1DOF_0_prop1" type="mesh" mesh="bumblebee_cw_prop" mass="0.00001" pos="-0.074 -0.087 0.036" rgba="0.1 0.02 0.5 1.0" />
			</body>
			<site name="HookedBumblebee1DOF_0_prop1" pos="-0.074 -0.087 0.036" size="0.0001" />
			<body name="HookedBumblebee1DOF_0_prop2">
				<joint name="HookedBumblebee1DOF_0_prop2" axis="0 0 1" pos="-0.074 0.087 0.036" />
				<geom name="HookedBumblebee1DOF_0_prop2" type="mesh" mesh="bumblebee_ccw_prop" mass="0.00001" pos="-0.074 0.087 0.036" rgba="0.1 0.02 0.5 1.0" />
			</body>
			<site name="HookedBumblebee1DOF_0_prop2" pos="-0.074 0.087 0.036" size="0.0001" />
			<body name="HookedBumblebee1DOF_0_prop3">
				<joint name="HookedBumblebee1DOF_0_prop3" axis="0 0 1" pos="0.091 0.087 0.036" />
				<geom name="HookedBumblebee1DOF_0_prop3" type="mesh" mesh="bumblebee_cw_prop" mass="0.00001" pos="0.091 0.087 0.036" rgba="0.1 0.02 0.5 1.0" />
			</body>
			<site name="HookedBumblebee1DOF_0_prop3" pos="0.091 0.087 0.036" size="0.0001" />
			<body name="HookedBumblebee1DOF_0_hook" pos="0.0085 0 0">
				<site name="HookedBumblebee1DOF_0_hook_base" pos="0 0 0.4" type="sphere" size="0.002" />
				<joint name="HookedBumblebee1DOF_0_hook" axis="0 1 0" pos="0 0 0" damping="0.001" />
				<geom name="HookedBumblebee1DOF_0_rod" type="cylinder" fromto="0 0 0  0 0 -0.4" size="0.005" mass="0.0" />
				<body name="HookedBumblebee1DOF_0_hook_head" pos="0 0 -0.4" euler="0 3.141592 0">
					<geom type="box" pos="0 0 0.02" size="0.003 0.003 0.02" mass="0.02" />
					<geom type="box" pos="0 0.019 0.054" euler="-0.92 0 0" size="0.003 0.003 0.026" mass="0.0001" />
					<geom type="box" pos="0 0.02 0.0825" euler="0.92 0 0" size="0.003 0.003 0.026" mass="0.0001" />
					<geom type="box" pos="0 -0.018 0.085" euler="-1.0472 0 0" size="0.003 0.003 0.026" mass="0.0001" />
				</body>
			</body>
		</body>
		<body name="DynamicPayload_0" pos="-0.9 0 1" quat="1 0 0 0">
			<joint name="DynamicPayload_0" type="free" />
			<geom name="DynamicPayload_0" type="mesh" mesh="payload_simplified" pos="0 0 0.0405" rgba="0 0 0 1" euler="1.57 0 0" mass="0.0001" />
			<geom name="DynamicPayload_0_bottom" type="box" size=".016 .016 .02" pos="0 0 0.0175" mass="0.07" rgba="1.0 1.0 1.0 0.0" />
			<geom type="capsule" pos="0 0 0.075" size="0.004 0.027" rgba="0 0 0 1" mass="0.0001" />
			<geom type="capsule" pos="0 0.01173 0.10565" euler="-1.12200 0 0" size="0.004 0.01562" rgba="0 0 0 1" mass="0.0001" />
			<geom type="capsule" pos="0 0.01061 0.10439" euler="-1.17810 0 0" size="0.004 0.01378" rgba="0 0 0 1" mass="0.0001" />
			<geom type="capsule" pos="0 0.02561 0.11939" euler="-0.39270 0 0" size="0.004 0.01378" rgba="0 0 0 1" mass="0.0001" />
			<geom type="capsule" pos="0 0.02561 0.14061" euler="0.39270 0 0" size="0.004 0.01378" rgba="0 0 0 1" mass="0.0001" />
			<geom type="capsule" pos="0 0.01061 0.15561" euler="1.17810 0 0" size="0.004 0.01378" rgba="0 0 0 1" mass="0.0001" />
			<geom type="capsule" pos="0 -0.01061 0.15561" euler="1.96350 0 0" size="0.004 0.01378" rgba="0 0 0 1" mass="0.0001" />
			<geom type="capsule" pos="0 -0.02561 0.14061" euler="2.74889 0 0" size="0.004 0.008" rgba="0 0 0 1" mass="0.0001" />
		</body>
		<body name="MocapPayload_0" pos="0 0 0.5" quat="0 1 0 0" mocap="true">
			<geom name="MocapPayload_0" type="mesh" mesh="payload_simplified" pos="0 0 0.0405" rgba="0 0 0 1" euler="1.57 0 0" />
			<geom type="capsule" pos="0 0 0.075" size="0.004 0.027" rgba="0 0 0 1" />
			<geom type="capsule" pos="0 0.01173 0.10565" euler="-1.12200 0 0" size="0.004 0.01562" rgba="0 0 0 1" />
			<geom type="capsule" pos="0 0.01061 0.10439" euler="-1.17810 0 0" size="0.004 0.01378" rgba="0 0 0 1" />
			<geom type="capsule" pos="0 0.02561 0.11939" euler="-0.39270 0 0" size="0.004 0.01378" rgba="0 0 0 1" />
			<geom type="capsule" pos="0 0.02561 0.14061" euler="0.39270 0 0" size="0.004 0.01378" rgba="0 0 0 1" />
			<geom type="capsule" pos="0 0.01061 0.15561" euler="1.17810 0 0" size="0.004 0.01378" rgba="0 0 0 1" />
			<geom type="capsule" pos="0 -0.01061 0.15561" euler="1.96350 0 0" size="0.004 0.01378" rgba="0 0 0 1" />
			<geom type="capsule" pos="0 -0.02561 0.14061" euler="2.74889 0 0" size="0.004 0.008" rgba="0 0 0 1" />
		</body>
	</worldbody>
	<actuator>
		<motor name="Bicycle_0_actr" joint="Bicycle_0_wheelr" />
		<general site="HookedBumblebee1DOF_0_prop0" name="HookedBumblebee1DOF_0_actr0" gear="0 0 1 0 0 0.5954" ctrllimited="true" ctrlrange="0 15" />
		<general site="HookedBumblebee1DOF_0_prop1" name="HookedBumblebee1DOF_0_actr1" gear="0 0 1 0 0 -0.5954" ctrllimited="true" ctrlrange="0 15" />
		<general site="HookedBumblebee1DOF_0_prop2" name="HookedBumblebee1DOF_0_actr2" gear="0 0 1 0 0 0.5954" ctrllimited="true" ctrlrange="0 15" />
		<general site="HookedBumblebee1DOF_0_prop3" name="HookedBumblebee1DOF_0_actr3" gear="0 0 1 0 0 -0.5954" ctrllimited="true" ctrlrange="0 15" />
	</actuator>
	<sensor>
		<velocimeter site="Bicycle_0_cog" name="Bicycle_0_velocimeter" />
		<gyro site="HookedBumblebee1DOF_0_cog" name="HookedBumblebee1DOF_0_gyro" />
		<framelinvel objtype="site" objname="HookedBumblebee1DOF_0_cog" name="HookedBumblebee1DOF_0_velocimeter" />
		<accelerometer site="HookedBumblebee1DOF_0_cog" name="HookedBumblebee1DOF_0_accelerometer" />
		<framepos objtype="site" objname="HookedBumblebee1DOF_0_cog" name="HookedBumblebee1DOF_0_posimeter" />
		<framequat objtype="site" objname="HookedBumblebee1DOF_0_cog" name="HookedBumblebee1DOF_0_orimeter" />
		<frameangacc objtype="site" objname="HookedBumblebee1DOF_0_cog" name="HookedBumblebee1DOF_0_ang_accelerometer" />
		<framepos objtype="site" objname="HookedBumblebee1DOF_0_hook_base" name="HookedBumblebee1DOF_0_hook_pos" />
		<framelinvel objtype="site" objname="HookedBumblebee1DOF_0_hook_base" name="HookedBumblebee1DOF_0_hook_vel" />
		<framequat objtype="site" objname="HookedBumblebee1DOF_0_hook_base" name="HookedBumblebee1DOF_0_hook_quat" />
		<frameangvel objtype="site" objname="HookedBumblebee1DOF_0_hook_base" name="HookedBumblebee1DOF_0_hook_ang_vel" />
	</sensor>
</mujoco>