<mujoco><include file="../xml_models/scene.xml" /><worldbody><body name="car0" pos="1.82338 -0.045190975 0" quat="0.0699114128947258 0.03419815003871918 -0.010923014022409916 -0.9969069957733154" mocap="true"><geom name="car0" type="box" size=".1 .13 .02" pos="-.07 0 0" rgba=".2 .2 .9 1.0" /><geom name="car0_front" type="box" size=".07 .07 .02" pos=".13 0 0" rgba=".2 .2 .9 1.0" /><geom name="car_pole" type="cylinder" size="0.01 0.5" pos="-.2 0 0.5" rgba="0.3 0.3 0.3 1.0" /><body name="car0_wheelfl" pos="0.2 .12 0" quat="1 0 0 0"><joint name="car0_wheelfl_steer" type="hinge" axis="0 0 1" /><joint name="car0_wheelfl" type="hinge" axis="0 1 0" /><geom name="car0_wheelfl" type="cylinder" size=".06 .02" material="material_check" euler="1.571 0 0" /></body><body name="car0_wheelrl" pos="-0.2 .12 0" quat="1 0 0 0"><joint name="car0_wheelrl_steer" type="hinge" axis="0 0 1" /><joint name="car0_wheelrl" type="hinge" axis="0 1 0" /><geom name="car0_wheelrl" type="cylinder" size=".06 .02" material="material_check" euler="1.571 0 0" /></body><body name="car0_wheelfr" pos="0.2 -.12 0" quat="1 0 0 0"><joint name="car0_wheelfr" type="hinge" axis="0 1 0" /><geom name="car0_wheelfr" type="cylinder" size=".06 .02" material="material_check" euler="1.571 0 0" /></body><body name="car0_wheelrr" pos="-0.2 -.12 0" quat="1 0 0 0"><joint name="car0_wheelrr" type="hinge" axis="0 1 0" /><geom name="car0_wheelrr" type="cylinder" size=".06 .02" material="material_check" euler="1.571 0 0" /></body></body><body name="lz_cf1" pos="1.4235928 0.31708455 0" quat="1 0 0 0"><geom class="landing_zone" /></body><body name="realcrazyflie_0" pos="1.4235928 0.31708455 0.033111308" quat="-0.9996786117553711 0.021207503974437714 -0.007741831708699465 -0.011535968631505966" mocap="true"><geom name="realcrazyflie_0_body" type="mesh" mesh="drone_body" rgba="0.2 0.2 0.85 1.0" /><geom name="realcrazyflie_0_4_motormounts" type="mesh" mesh="drone_4_motormounts" rgba="0.2 0.2 0.85 1.0" /><geom name="realcrazyflie_0_4_motors" type="mesh" mesh="drone_4_motors" rgba="0.2 0.2 0.85 1.0" /></body><body name="realcrazyflie_0_prop1" pos="0.047 0.047 0.032" quat="-0.9996786117553711 0.021207503974437714 -0.007741831708699465 -0.011535968631505966" mocap="true"><geom name="realcrazyflie_0_prop1" type="mesh" mesh="drone_ccw_prop" pos="0.047 0.047 0.032" rgba="0.1 0.1 0.1 1.0" euler="0 0 -0.785" /></body><body name="realcrazyflie_0_prop2" pos="-0.047 -0.047 0.032" quat="-0.9996786117553711 0.021207503974437714 -0.007741831708699465 -0.011535968631505966" mocap="true"><geom name="realcrazyflie_0_prop2" type="mesh" mesh="drone_ccw_prop" pos="-0.047 -0.047 0.032" rgba="0.1 0.1 0.1 1.0" euler="0 0 -0.785" /></body><body name="realcrazyflie_0_prop3" pos="-0.047 0.047 0.032" quat="-0.9996786117553711 0.021207503974437714 -0.007741831708699465 -0.011535968631505966" mocap="true"><geom name="realcrazyflie_0_prop3" type="mesh" mesh="drone_cw_prop" pos="-0.047 0.047 0.032" rgba="0.1 0.1 0.1 1.0" euler="0 0 -0.785" /></body><body name="realcrazyflie_0_prop4" pos="0.047 -0.047 0.032" quat="-0.9996786117553711 0.021207503974437714 -0.007741831708699465 -0.011535968631505966" mocap="true"><geom name="realcrazyflie_0_prop4" type="mesh" mesh="drone_cw_prop" pos="0.047 -0.047 0.032" rgba="0.1 0.1 0.1 1.0" euler="0 0 -0.785" /></body><body name="lz_cf10" pos="-0.84042555 -1.0342729 0" quat="1 0 0 0"><geom class="landing_zone" /></body><body name="realcrazyflie_1" pos="-0.84042555 -1.0342729 0.006866897" quat="-0.9762550592422485 -0.022086860612034798 -0.007237219251692295 -0.2153741419315338" mocap="true"><geom name="realcrazyflie_1_body" type="mesh" mesh="drone_body" rgba="0.2 0.2 0.85 1.0" /><geom name="realcrazyflie_1_4_motormounts" type="mesh" mesh="drone_4_motormounts" rgba="0.2 0.2 0.85 1.0" /><geom name="realcrazyflie_1_4_motors" type="mesh" mesh="drone_4_motors" rgba="0.2 0.2 0.85 1.0" /></body><body name="realcrazyflie_1_prop1" pos="0.047 0.047 0.032" quat="-0.9762550592422485 -0.022086860612034798 -0.007237219251692295 -0.2153741419315338" mocap="true"><geom name="realcrazyflie_1_prop1" type="mesh" mesh="drone_ccw_prop" pos="0.047 0.047 0.032" rgba="0.1 0.1 0.1 1.0" euler="0 0 -0.785" /></body><body name="realcrazyflie_1_prop2" pos="-0.047 -0.047 0.032" quat="-0.9762550592422485 -0.022086860612034798 -0.007237219251692295 -0.2153741419315338" mocap="true"><geom name="realcrazyflie_1_prop2" type="mesh" mesh="drone_ccw_prop" pos="-0.047 -0.047 0.032" rgba="0.1 0.1 0.1 1.0" euler="0 0 -0.785" /></body><body name="realcrazyflie_1_prop3" pos="-0.047 0.047 0.032" quat="-0.9762550592422485 -0.022086860612034798 -0.007237219251692295 -0.2153741419315338" mocap="true"><geom name="realcrazyflie_1_prop3" type="mesh" mesh="drone_cw_prop" pos="-0.047 0.047 0.032" rgba="0.1 0.1 0.1 1.0" euler="0 0 -0.785" /></body><body name="realcrazyflie_1_prop4" pos="0.047 -0.047 0.032" quat="-0.9762550592422485 -0.022086860612034798 -0.007237219251692295 -0.2153741419315338" mocap="true"><geom name="realcrazyflie_1_prop4" type="mesh" mesh="drone_cw_prop" pos="0.047 -0.047 0.032" rgba="0.1 0.1 0.1 1.0" euler="0 0 -0.785" /></body><body name="lz_cf2" pos="-1.3373873 0.019147297 0" quat="1 0 0 0"><geom class="landing_zone" /></body><body name="realcrazyflie_2" pos="-1.3373873 0.019147297 0.0016266156" quat="-0.5848386883735657 0.004553751554340124 -0.019970865920186043 -0.8108909130096436" mocap="true"><geom name="realcrazyflie_2_body" type="mesh" mesh="drone_body" rgba="0.2 0.2 0.85 1.0" /><geom name="realcrazyflie_2_4_motormounts" type="mesh" mesh="drone_4_motormounts" rgba="0.2 0.2 0.85 1.0" /><geom name="realcrazyflie_2_4_motors" type="mesh" mesh="drone_4_motors" rgba="0.2 0.2 0.85 1.0" /></body><body name="realcrazyflie_2_prop1" pos="0.047 0.047 0.032" quat="-0.5848386883735657 0.004553751554340124 -0.019970865920186043 -0.8108909130096436" mocap="true"><geom name="realcrazyflie_2_prop1" type="mesh" mesh="drone_ccw_prop" pos="0.047 0.047 0.032" rgba="0.1 0.1 0.1 1.0" euler="0 0 -0.785" /></body><body name="realcrazyflie_2_prop2" pos="-0.047 -0.047 0.032" quat="-0.5848386883735657 0.004553751554340124 -0.019970865920186043 -0.8108909130096436" mocap="true"><geom name="realcrazyflie_2_prop2" type="mesh" mesh="drone_ccw_prop" pos="-0.047 -0.047 0.032" rgba="0.1 0.1 0.1 1.0" euler="0 0 -0.785" /></body><body name="realcrazyflie_2_prop3" pos="-0.047 0.047 0.032" quat="-0.5848386883735657 0.004553751554340124 -0.019970865920186043 -0.8108909130096436" mocap="true"><geom name="realcrazyflie_2_prop3" type="mesh" mesh="drone_cw_prop" pos="-0.047 0.047 0.032" rgba="0.1 0.1 0.1 1.0" euler="0 0 -0.785" /></body><body name="realcrazyflie_2_prop4" pos="0.047 -0.047 0.032" quat="-0.5848386883735657 0.004553751554340124 -0.019970865920186043 -0.8108909130096436" mocap="true"><geom name="realcrazyflie_2_prop4" type="mesh" mesh="drone_cw_prop" pos="0.047 -0.047 0.032" rgba="0.1 0.1 0.1 1.0" euler="0 0 -0.785" /></body><body name="lz_cf5" pos="-0.9524365 -0.70478535 0" quat="1 0 0 0"><geom class="landing_zone" /></body><body name="realcrazyflie_3" pos="-0.9524365 -0.70478535 0.0033745945" quat="-0.9964773654937744 0.00979092251509428 0.013895121403038502 -0.08212201297283173" mocap="true"><geom name="realcrazyflie_3_body" type="mesh" mesh="drone_body" rgba="0.2 0.2 0.85 1.0" /><geom name="realcrazyflie_3_4_motormounts" type="mesh" mesh="drone_4_motormounts" rgba="0.2 0.2 0.85 1.0" /><geom name="realcrazyflie_3_4_motors" type="mesh" mesh="drone_4_motors" rgba="0.2 0.2 0.85 1.0" /></body><body name="realcrazyflie_3_prop1" pos="0.047 0.047 0.032" quat="-0.9964773654937744 0.00979092251509428 0.013895121403038502 -0.08212201297283173" mocap="true"><geom name="realcrazyflie_3_prop1" type="mesh" mesh="drone_ccw_prop" pos="0.047 0.047 0.032" rgba="0.1 0.1 0.1 1.0" euler="0 0 -0.785" /></body><body name="realcrazyflie_3_prop2" pos="-0.047 -0.047 0.032" quat="-0.9964773654937744 0.00979092251509428 0.013895121403038502 -0.08212201297283173" mocap="true"><geom name="realcrazyflie_3_prop2" type="mesh" mesh="drone_ccw_prop" pos="-0.047 -0.047 0.032" rgba="0.1 0.1 0.1 1.0" euler="0 0 -0.785" /></body><body name="realcrazyflie_3_prop3" pos="-0.047 0.047 0.032" quat="-0.9964773654937744 0.00979092251509428 0.013895121403038502 -0.08212201297283173" mocap="true"><geom name="realcrazyflie_3_prop3" type="mesh" mesh="drone_cw_prop" pos="-0.047 0.047 0.032" rgba="0.1 0.1 0.1 1.0" euler="0 0 -0.785" /></body><body name="realcrazyflie_3_prop4" pos="0.047 -0.047 0.032" quat="-0.9964773654937744 0.00979092251509428 0.013895121403038502 -0.08212201297283173" mocap="true"><geom name="realcrazyflie_3_prop4" type="mesh" mesh="drone_cw_prop" pos="0.047 -0.047 0.032" rgba="0.1 0.1 0.1 1.0" euler="0 0 -0.785" /></body></worldbody><actuator /><sensor /></mujoco>