<mujoco><include file="../xml_models/scene.xml" /><worldbody><body name="car0" pos="1.5866016 -0.20147784 0" quat="0.006784701719880104 -0.023883571848273277 0.012179186567664146 0.9996176362037659" mocap="true"><geom name="car0_chassis_b" type="box" size=".1016 .10113 .02" pos="-.06 0 0" rgba=".2 .2 .9 1.0" /><geom name="car0_chassis_f" type="box" size=".07 .06 .02" pos=".10113 0 0" rgba=".2 .2 .9 1.0" /><geom name="car0_front" type="box" size=".02 .052388 .02" pos=".2135 0 0" rgba=".2 .2 .9 1.0" /><geom name="car0_back" type="box" size=".02 .052388 .02" pos="-.2135 0 0" rgba=".2 .2 .9 1.0" /><geom name="car0_front_bumper" type="box" size=".09 .005 .02" pos=".265888 0 0.02" rgba=".2 .2 .9 1.0" /><geom name="car0_back_bumper" type="box" size=".08 .005 .02" pos="-.265888 0 0.02" rgba=".2 .2 .9 1.0" /><geom name="car_pole" type="cylinder" size="0.01 0.47625" pos="-.2135 0 0.47625" rgba="0.3 0.3 0.3 1.0" /><body name="car0_wheelfl" quat="1 0 0 0"><joint name="car0_wheelfl" type="hinge" pos="0.16113 .122385 0" axis="0 1 0" /><geom name="car0_wheelfl" type="cylinder" size=".052388 .022225" pos="0.16113 .122385 0" material="material_check" euler="1.571 0 0" /></body><body name="car0_wheelrl" quat="1 0 0 0"><joint name="car0_wheelrl" type="hinge" pos="-0.16113 .122385 0" axis="0 1 0" /><geom name="car0_wheelrl" type="cylinder" size=".052388 .022225" pos="-0.16113 .122385 0" material="material_check" euler="1.571 0 0" /></body><body name="car0_wheelfr" quat="1 0 0 0"><joint name="car0_wheelfr" type="hinge" pos="0.16113 -.122385 0" axis="0 1 0" /><geom name="car0_wheelfr" type="cylinder" size=".052388 .022225" pos="0.16113 -.122385 0" material="material_check" euler="1.571 0 0" /></body><body name="car0_wheelrr" quat="1 0 0 0"><joint name="car0_wheelrr" type="hinge" pos="-0.16113 -.122385 0" axis="0 1 0" /><geom name="car0_wheelrr" type="cylinder" size=".052388 .022225" pos="-0.16113 -.122385 0" material="material_check" euler="1.571 0 0" /></body></body></worldbody><actuator /><sensor /></mujoco>