<mujoco><include file="../xml_models/scene.xml" /><worldbody><body name="realbumblebee_hooked_0" pos="0 0 1" quat="1 0 0 0" mocap="true"><geom name="realbumblebee_hooked_0_body" pos="0.0132 0 0" type="mesh" quat="-0.7071067811865475 -0.0 0.0 0.7071067811865476" mesh="drone_body_large" rgba="0.2 0.2 0.85 1.0" /><body name="realbumblebee_hooked_0_prop1" quat="1 0 0 0"><joint name="realbumblebee_hooked_0_prop1" axis="0 0 1" pos="-0.074 0.087 0.036" /><geom name="realbumblebee_hooked_0_prop1" type="mesh" mesh="drone_ccw_prop_large" pos="-0.074 0.087 0.036" rgba="0.1 0.1 0.1 1.0" /></body><body name="realbumblebee_hooked_0_prop2" quat="1 0 0 0"><joint name="realbumblebee_hooked_0_prop2" axis="0 0 1" pos="0.091 -0.087 0.036" /><geom name="realbumblebee_hooked_0_prop2" type="mesh" mesh="drone_ccw_prop_large" pos="0.091 -0.087 0.036" rgba="0.1 0.1 0.1 1.0" /></body><body name="realbumblebee_hooked_0_prop3" quat="1 0 0 0"><joint name="realbumblebee_hooked_0_prop3" axis="0 0 1" pos="0.091 0.087 0.036" /><geom name="realbumblebee_hooked_0_prop3" type="mesh" mesh="drone_cw_prop_large" pos="0.091 0.087 0.036" rgba="0.1 0.1 0.1 1.0" /></body><body name="realbumblebee_hooked_0_prop4" quat="1 0 0 0"><joint name="realbumblebee_hooked_0_prop4" axis="0 0 1" pos="-0.074 -0.087 0.036" /><geom name="realbumblebee_hooked_0_prop4" type="mesh" mesh="drone_cw_prop_large" pos="-0.074 -0.087 0.036" rgba="0.1 0.1 0.1 1.0" /></body></body><body name="realbumblebee_hooked_0_hook" pos="0 0 1" mocap="true"><geom type="cylinder" fromto="0 0 0  0 0 -0.4" size="0.0025" /><geom type="capsule" pos="0 0 -0.38" size="0.002 0.02" /><geom type="capsule" pos="-0.01299 0 -0.4475" euler="0 -1.0472 0" size="0.005 0.018" /><geom type="capsule" pos="-0.02598 0 -0.42500000000000004" euler="0 0 0" size="0.005 0.018" /><geom type="capsule" pos="-0.01299 0 -0.405" euler="0 1.0472 0" size="0.005 0.018" /><geom type="capsule" pos="0.01299 0 -0.4475" euler="0 1.0472 0" size="0.005 0.018" /></body><body name="realcrazyflie_0" pos="1 1 1" quat="1 0 0 0" mocap="true"><geom name="realcrazyflie_0_body" type="mesh" mesh="drone_body" rgba="0.2 0.2 0.85 1.0" /><geom name="realcrazyflie_0_4_motormounts" type="mesh" mesh="drone_4_motormounts" rgba="0.2 0.2 0.85 1.0" /><geom name="realcrazyflie_0_4_motors" type="mesh" mesh="drone_4_motors" rgba="0.2 0.2 0.85 1.0" /><body name="realcrazyflie_0_prop1" quat="1 0 0 0"><joint name="realcrazyflie_0_prop1" axis="0 0 1" pos="0.047 0.047 0.032" /><geom name="realcrazyflie_0_prop1" type="mesh" mesh="drone_ccw_prop" pos="0.047 0.047 0.032" rgba="0.1 0.1 0.1 1.0" euler="0 0 -0.785" /></body><body name="realcrazyflie_0_prop2" quat="1 0 0 0"><joint name="realcrazyflie_0_prop2" axis="0 0 1" pos="-0.047 -0.047 0.032" /><geom name="realcrazyflie_0_prop2" type="mesh" mesh="drone_ccw_prop" pos="-0.047 -0.047 0.032" rgba="0.1 0.1 0.1 1.0" euler="0 0 -0.785" /></body><body name="realcrazyflie_0_prop3" quat="1 0 0 0"><joint name="realcrazyflie_0_prop3" axis="0 0 1" pos="-0.047 0.047 0.032" /><geom name="realcrazyflie_0_prop3" type="mesh" mesh="drone_cw_prop" pos="-0.047 0.047 0.032" rgba="0.1 0.1 0.1 1.0" euler="0 0 -0.785" /></body><body name="realcrazyflie_0_prop4" quat="1 0 0 0"><joint name="realcrazyflie_0_prop4" axis="0 0 1" pos="0.047 -0.047 0.032" /><geom name="realcrazyflie_0_prop4" type="mesh" mesh="drone_cw_prop" pos="0.047 -0.047 0.032" rgba="0.1 0.1 0.1 1.0" euler="0 0 -0.785" /></body></body><body name="realbumblebee_0" pos="1 0 1" quat="1 0 0 0" mocap="true"><geom name="realbumblebee_0_body" pos="0.0132 0 0" type="mesh" quat="-0.7071067811865475 -0.0 0.0 0.7071067811865476" mesh="drone_body_large" rgba="0.2 0.2 0.85 1.0" /><body name="realbumblebee_0_prop1" quat="1 0 0 0"><joint name="realbumblebee_0_prop1" axis="0 0 1" pos="-0.074 0.087 0.036" /><geom name="realbumblebee_0_prop1" type="mesh" mesh="drone_ccw_prop_large" pos="-0.074 0.087 0.036" rgba="0.1 0.1 0.1 1.0" /></body><body name="realbumblebee_0_prop2" quat="1 0 0 0"><joint name="realbumblebee_0_prop2" axis="0 0 1" pos="0.091 -0.087 0.036" /><geom name="realbumblebee_0_prop2" type="mesh" mesh="drone_ccw_prop_large" pos="0.091 -0.087 0.036" rgba="0.1 0.1 0.1 1.0" /></body><body name="realbumblebee_0_prop3" quat="1 0 0 0"><joint name="realbumblebee_0_prop3" axis="0 0 1" pos="0.091 0.087 0.036" /><geom name="realbumblebee_0_prop3" type="mesh" mesh="drone_cw_prop_large" pos="0.091 0.087 0.036" rgba="0.1 0.1 0.1 1.0" /></body><body name="realbumblebee_0_prop4" quat="1 0 0 0"><joint name="realbumblebee_0_prop4" axis="0 0 1" pos="-0.074 -0.087 0.036" /><geom name="realbumblebee_0_prop4" type="mesh" mesh="drone_cw_prop_large" pos="-0.074 -0.087 0.036" rgba="0.1 0.1 0.1 1.0" /></body></body></worldbody><contact /><actuator /><sensor /></mujoco>