<mujoco><include file="../xml_models/scene.xml" /><worldbody><body name="virtbumblebee_0" pos="1 1 1" quat="1 0 0 0"><inertial pos="0 0 0" diaginertia="1.5e-3 1.45e-3 2.66e-3" mass="0.407" /><joint name="virtbumblebee_0" type="free" /><geom name="virtbumblebee_0_body" pos="0.0132 0 0" type="mesh" quat="-0.7071067811865475 -0.0 0.0 0.7071067811865476" mesh="drone_body_large" rgba="0.85 0.2 0.2 1.0" /><site name="virtbumblebee_0_cog" pos="0 0 0" /><body name="virtbumblebee_0_prop1"><joint name="virtbumblebee_0_prop1" axis="0 0 1" pos="-0.074 0.087 0.036" /><geom name="virtbumblebee_0_prop1" type="mesh" mesh="drone_ccw_prop_large" mass="0.00001" pos="-0.074 0.087 0.036" rgba="0.1 0.02 0.5 1.0" /></body><body name="virtbumblebee_0_prop2"><joint name="virtbumblebee_0_prop2" axis="0 0 1" pos="0.091 -0.087 0.036" /><geom name="virtbumblebee_0_prop2" type="mesh" mesh="drone_ccw_prop_large" mass="0.00001" pos="0.091 -0.087 0.036" rgba="0.1 0.02 0.5 1.0" /></body><body name="virtbumblebee_0_prop3"><joint name="virtbumblebee_0_prop3" axis="0 0 1" pos="0.091 0.087 0.036" /><geom name="virtbumblebee_0_prop3" type="mesh" mesh="drone_cw_prop_large" mass="0.00001" pos="0.091 0.087 0.036" rgba="0.1 0.02 0.5 1.0" /></body><body name="virtbumblebee_0_prop4"><joint name="virtbumblebee_0_prop4" axis="0 0 1" pos="-0.074 -0.087 0.036" /><geom name="virtbumblebee_0_prop4" type="mesh" mesh="drone_cw_prop_large" mass="0.00001" pos="-0.074 -0.087 0.036" rgba="0.1 0.02 0.5 1.0" /></body></body></worldbody><contact /><actuator><general site="virtbumblebee_0_cog" name="virtbumblebee_0_actr0" gear=" 0 0 1 0 0 0" ctrllimited="true" ctrlrange="0 67.2" /><general site="virtbumblebee_0_cog" name="virtbumblebee_0_actr1" gear=" 0 0 0 1 0 0" ctrllimited="true" ctrlrange="-6 6" /><general site="virtbumblebee_0_cog" name="virtbumblebee_0_actr2" gear=" 0 0 0 0 1 0" ctrllimited="true" ctrlrange="-6 6" /><general site="virtbumblebee_0_cog" name="virtbumblebee_0_actr3" gear=" 0 0 0 0 0 1" ctrllimited="true" ctrlrange="-1.5 1.5" /></actuator><sensor><gyro site="virtbumblebee_0_cog" name="virtbumblebee_0_gyro" /></sensor></mujoco>