<mujoco><include file="../xml_models/scene.xml" /><worldbody><body name="virtbumblebee_hooked_0" pos="1 1 1" quat="1 0 0 0"><inertial pos="0 0 0" diaginertia="1.5e-3 1.45e-3 2.66e-3" mass="0.407" /><joint name="virtbumblebee_hooked_0" type="free" /><geom name="virtbumblebee_hooked_0_body" pos="0.0132 0 0" type="mesh" quat="-0.7071067811865475 -0.0 0.0 0.7071067811865476" mesh="drone_body_large" rgba="0.85 0.2 0.2 1.0" /><site name="virtbumblebee_hooked_0_cog" pos="0 0 0" /><body name="virtbumblebee_hooked_0_rod" pos="0 0 0"><geom type="cylinder" fromto="0 0 0  0 0 -0.4" size="0.0025" mass="0.00" /><site name="virtbumblebee_hooked_0_rod_end" pos="0 0 -0.4" type="sphere" size="0.002" /><joint name="virtbumblebee_hooked_0_hook" axis="0 1 0" pos="0 0 0" damping="0.001" /><body name="virtbumblebee_hooked_0_hook" pos="0 0 -0.4" euler="0 3.141592 -1.57"><geom type="capsule" pos="0 0 0.02" size="0.002 0.02" mass="0.02" /><geom type="capsule" pos="0 0.01299 0.0475" euler="-1.0472 0 0" size="0.005 0.018" mass="0.0001" /><geom type="capsule" pos="0 0.02598 0.07" euler="0 0 0" size="0.005 0.018" mass="0.0001" /><geom type="capsule" pos="0 0.01299 0.0925" euler="1.0472 0 0" size="0.005 0.018" mass="0.0001" /><geom type="capsule" pos="0 -0.01299 0.0925" euler="2.0944 0 0" size="0.005 0.018" mass="0.0001" /></body></body><body name="virtbumblebee_hooked_0_prop1"><joint name="virtbumblebee_hooked_0_prop1" axis="0 0 1" pos="-0.074 0.087 0.036" /><geom name="virtbumblebee_hooked_0_prop1" type="mesh" mesh="drone_ccw_prop_large" mass="0.00001" pos="-0.074 0.087 0.036" rgba="0.1 0.02 0.5 1.0" /></body><body name="virtbumblebee_hooked_0_prop2"><joint name="virtbumblebee_hooked_0_prop2" axis="0 0 1" pos="0.091 -0.087 0.036" /><geom name="virtbumblebee_hooked_0_prop2" type="mesh" mesh="drone_ccw_prop_large" mass="0.00001" pos="0.091 -0.087 0.036" rgba="0.1 0.02 0.5 1.0" /></body><body name="virtbumblebee_hooked_0_prop3"><joint name="virtbumblebee_hooked_0_prop3" axis="0 0 1" pos="0.091 0.087 0.036" /><geom name="virtbumblebee_hooked_0_prop3" type="mesh" mesh="drone_cw_prop_large" mass="0.00001" pos="0.091 0.087 0.036" rgba="0.1 0.02 0.5 1.0" /></body><body name="virtbumblebee_hooked_0_prop4"><joint name="virtbumblebee_hooked_0_prop4" axis="0 0 1" pos="-0.074 -0.087 0.036" /><geom name="virtbumblebee_hooked_0_prop4" type="mesh" mesh="drone_cw_prop_large" mass="0.00001" pos="-0.074 -0.087 0.036" rgba="0.1 0.02 0.5 1.0" /></body></body><body name="realcrazyflie_0" pos="0 1 0" quat="1 0 0 0" mocap="true"><geom name="realcrazyflie_0_body" type="mesh" mesh="drone_body" rgba="0.2 0.2 0.85 1.0" /><geom name="realcrazyflie_0_4_motormounts" type="mesh" mesh="drone_4_motormounts" rgba="0.2 0.2 0.85 1.0" /><geom name="realcrazyflie_0_4_motors" type="mesh" mesh="drone_4_motors" rgba="0.2 0.2 0.85 1.0" /></body><body name="realcrazyflie_0_prop1" pos="0.047 0.047 0.032" quat="1 0 0 0" mocap="true"><geom name="realcrazyflie_0_prop1" type="mesh" mesh="drone_ccw_prop" pos="0.047 0.047 0.032" rgba="0.1 0.1 0.1 1.0" euler="0 0 -0.785" /></body><body name="realcrazyflie_0_prop2" pos="-0.047 -0.047 0.032" quat="1 0 0 0" mocap="true"><geom name="realcrazyflie_0_prop2" type="mesh" mesh="drone_ccw_prop" pos="-0.047 -0.047 0.032" rgba="0.1 0.1 0.1 1.0" euler="0 0 -0.785" /></body><body name="realcrazyflie_0_prop3" pos="-0.047 0.047 0.032" quat="1 0 0 0" mocap="true"><geom name="realcrazyflie_0_prop3" type="mesh" mesh="drone_cw_prop" pos="-0.047 0.047 0.032" rgba="0.1 0.1 0.1 1.0" euler="0 0 -0.785" /></body><body name="realcrazyflie_0_prop4" pos="0.047 -0.047 0.032" quat="1 0 0 0" mocap="true"><geom name="realcrazyflie_0_prop4" type="mesh" mesh="drone_cw_prop" pos="0.047 -0.047 0.032" rgba="0.1 0.1 0.1 1.0" euler="0 0 -0.785" /></body><body name="virtfleet1tenth_0" pos="-0.5 1 0.2" quat="1 0 0 0"><joint name="virtfleet1tenth_0" type="free" /><geom name="virtfleet1tenth_0_chassis_b" type="box" size=".1016 .10113 .02" pos="-.06 0 0" euler="0 0 1.570796" rgba="0.85 0.2 0.2 1.0" /><geom name="virtfleet1tenth_0_chassis_f" type="box" size=".07 .06 .02" pos=".10113 0 0" euler="0 0 1.570796" rgba="0.85 0.2 0.2 1.0" /><geom name="virtfleet1tenth_0_front" type="box" size=".02 .052388 .02" pos=".2135 0 0" euler="0 0 1.570796" rgba="0.85 0.2 0.2 1.0" /><geom name="virtfleet1tenth_0_back" type="box" size=".02 .052388 .02" pos="-.2135 0 0" euler="0 0 1.570796" rgba="0.85 0.2 0.2 1.0" /><geom name="virtfleet1tenth_0_front_bumper" type="box" size=".09 .005 .02" pos=".265888 0 0.02" euler="0 0 1.570796" rgba="0.85 0.2 0.2 1.0" /><geom name="virtfleet1tenth_0_back_bumper" type="box" size=".08 .005 .02" pos="-.265888 0 0.02" euler="0 0 1.570796" rgba="0.85 0.2 0.2 1.0" /><body name="virtfleet1tenth_0_wheelfl" quat="1 0 0 0"><joint name="virtfleet1tenth_0_wheelfl_steer" type="hinge" pos="0.16113 .122385 0" axis="0 0 1" /><joint name="virtfleet1tenth_0_wheelfl" type="hinge" pos="0.16113 .122385 0" axis="0 1 0" /><geom name="virtfleet1tenth_0_wheelfl" type="cylinder" size=".052388 .022225" pos="0.16113 .122385 0" material="material_check" euler="1.571 0 0" /></body><body name="virtfleet1tenth_0_wheelrl" quat="1 0 0 0"><joint name="virtfleet1tenth_0_wheelrl" type="hinge" pos="-0.16113 .122385 0" axis="0 1 0" /><geom name="virtfleet1tenth_0_wheelrl" type="cylinder" size=".052388 .022225" pos="-0.16113 .122385 0" material="material_check" euler="1.571 0 0" /></body><body name="virtfleet1tenth_0_wheelfr" quat="1 0 0 0"><joint name="virtfleet1tenth_0_wheelfr_steer" type="hinge" pos="0.16113 -.122385 0" axis="0 0 1" /><joint name="virtfleet1tenth_0_wheelfr" type="hinge" pos="0.16113 -.122385 0" axis="0 1 0" /><geom name="virtfleet1tenth_0_wheelfr" type="cylinder" size=".052388 .022225" pos="0.16113 -.122385 0" material="material_check" euler="1.571 0 0" /></body><body name="virtfleet1tenth_0_wheelrr" quat="1 0 0 0"><joint name="virtfleet1tenth_0_wheelrr" type="hinge" pos="-0.16113 -.122385 0" axis="0 1 0" /><geom name="virtfleet1tenth_0_wheelrr" type="cylinder" size=".052388 .022225" pos="-0.16113 -.122385 0" material="material_check" euler="1.571 0 0" /></body></body><body name="realfleet1tenth_0" pos="0.5 1 0.2" quat="1 0 0 0" mocap="true"><geom name="realfleet1tenth_0_chassis_b" type="box" size=".1016 .10113 .02" pos="-.06 0 0" euler="0 0 1.570796" rgba="0.2 0.2 0.85 1.0" /><geom name="realfleet1tenth_0_chassis_f" type="box" size=".07 .06 .02" pos=".10113 0 0" euler="0 0 1.570796" rgba="0.2 0.2 0.85 1.0" /><geom name="realfleet1tenth_0_front" type="box" size=".02 .052388 .02" pos=".2135 0 0" euler="0 0 1.570796" rgba="0.2 0.2 0.85 1.0" /><geom name="realfleet1tenth_0_back" type="box" size=".02 .052388 .02" pos="-.2135 0 0" euler="0 0 1.570796" rgba="0.2 0.2 0.85 1.0" /><geom name="realfleet1tenth_0_front_bumper" type="box" size=".09 .005 .02" pos=".265888 0 0.02" euler="0 0 1.570796" rgba="0.2 0.2 0.85 1.0" /><geom name="realfleet1tenth_0_back_bumper" type="box" size=".08 .005 .02" pos="-.265888 0 0.02" euler="0 0 1.570796" rgba="0.2 0.2 0.85 1.0" /><body name="realfleet1tenth_0_wheelfl" quat="1 0 0 0"><geom name="realfleet1tenth_0_wheelfl" type="cylinder" size=".052388 .022225" pos="0.16113 .122385 0" rgba="0.1 0.1 0.1 1.0" euler="1.571 0 0" /></body><body name="realfleet1tenth_0_wheelrl" quat="1 0 0 0"><geom name="realfleet1tenth_0_wheelrl" type="cylinder" size=".052388 .022225" pos="-0.16113 .122385 0" rgba="0.1 0.1 0.1 1.0" euler="1.571 0 0" /></body><body name="realfleet1tenth_0_wheelfr" quat="1 0 0 0"><geom name="realfleet1tenth_0_wheelfr" type="cylinder" size=".052388 .022225" pos="0.16113 -.122385 0" rgba="0.1 0.1 0.1 1.0" euler="1.571 0 0" /></body><body name="realfleet1tenth_0_wheelrr" quat="1 0 0 0"><geom name="realfleet1tenth_0_wheelrr" type="cylinder" size=".052388 .022225" pos="-0.16113 -.122385 0" rgba="0.1 0.1 0.1 1.0" euler="1.571 0 0" /></body></body><body name="load_0" pos="0 0 0" quat="1 0 0 0"><geom type="box" size=".1 .1 .1" mass=".15" pos="0 0 .1" rgba="0.1 0.1 0.9 1.0" /><joint type="free" /><body name="load_0_hook" pos="0 0 0.2"><geom type="capsule" pos="0 0 0.02" size="0.002 0.02" mass="0.0001" /><geom type="capsule" pos="0 0.01173 0.04565" euler="-1.12200 0 0" size="0.004 0.01562" mass="0.0001" /><geom type="capsule" pos="0 0.01061 0.04439" euler="-1.17810 0 0" size="0.004 0.01378" mass="0.0001" /><geom type="capsule" pos="0 0.02561 0.05939" euler="-0.39270 0 0" size="0.004 0.01378" mass="0.0001" /><geom type="capsule" pos="0 0.02561 0.08061" euler="0.39270 0 0" size="0.004 0.01378" mass="0.0001" /><geom type="capsule" pos="0 0.01061 0.09561" euler="1.17810 0 0" size="0.004 0.01378" mass="0.0001" /><geom type="capsule" pos="0 -0.01061 0.09561" euler="1.96350 0 0" size="0.004 0.01378" mass="0.0001" /><geom type="capsule" pos="0 -0.02561 0.08061" euler="2.74889 0 0" size="0.004 0.01378" mass="0.0001" /></body></body><body name="load_1" pos="-.6 .6 0" quat="1 0 0 0"><geom type="box" size=".075 .075 .075" mass=".05" pos="0 0 .075" rgba="0.1 0.9 0.1 1.0" /><joint type="free" /><body name="load_1_hook" pos="0 0 0.15"><geom type="capsule" pos="0 0 0.02" size="0.002 0.02" mass="0.0001" /><geom type="capsule" pos="0 0.01173 0.04565" euler="-1.12200 0 0" size="0.004 0.01562" mass="0.0001" /><geom type="capsule" pos="0 0.01061 0.04439" euler="-1.17810 0 0" size="0.004 0.01378" mass="0.0001" /><geom type="capsule" pos="0 0.02561 0.05939" euler="-0.39270 0 0" size="0.004 0.01378" mass="0.0001" /><geom type="capsule" pos="0 0.02561 0.08061" euler="0.39270 0 0" size="0.004 0.01378" mass="0.0001" /><geom type="capsule" pos="0 0.01061 0.09561" euler="1.17810 0 0" size="0.004 0.01378" mass="0.0001" /><geom type="capsule" pos="0 -0.01061 0.09561" euler="1.96350 0 0" size="0.004 0.01378" mass="0.0001" /><geom type="capsule" pos="0 -0.02561 0.08061" euler="2.74889 0 0" size="0.004 0.01378" mass="0.0001" /></body></body><body name="load_2" pos="-.3 -.6 0" quat="1 0 0 0"><geom type="box" size=".075 .075 .1" mass=".1" pos="0 0 .1" rgba="0.9 0.1 0.1 1.0" /><joint type="free" /><body name="load_2_hook" pos="0 0 0.2"><geom type="capsule" pos="0 0 0.02" size="0.002 0.02" mass="0.0001" /><geom type="capsule" pos="0 0.01173 0.04565" euler="-1.12200 0 0" size="0.004 0.01562" mass="0.0001" /><geom type="capsule" pos="0 0.01061 0.04439" euler="-1.17810 0 0" size="0.004 0.01378" mass="0.0001" /><geom type="capsule" pos="0 0.02561 0.05939" euler="-0.39270 0 0" size="0.004 0.01378" mass="0.0001" /><geom type="capsule" pos="0 0.02561 0.08061" euler="0.39270 0 0" size="0.004 0.01378" mass="0.0001" /><geom type="capsule" pos="0 0.01061 0.09561" euler="1.17810 0 0" size="0.004 0.01378" mass="0.0001" /><geom type="capsule" pos="0 -0.01061 0.09561" euler="1.96350 0 0" size="0.004 0.01378" mass="0.0001" /><geom type="capsule" pos="0 -0.02561 0.08061" euler="2.74889 0 0" size="0.004 0.01378" mass="0.0001" /></body></body></worldbody><contact><pair geom1="virtfleet1tenth_0_wheelfl" geom2="roundabout" friction="1 1 0.005 0.0001 0.0001" /><pair geom1="virtfleet1tenth_0_wheelfr" geom2="roundabout" friction="1 1 0.005 0.0001 0.0001" /><pair geom1="virtfleet1tenth_0_wheelrl" geom2="roundabout" friction="1 1 0.005 0.0001 0.0001" /><pair geom1="virtfleet1tenth_0_wheelrr" geom2="roundabout" friction="1 1 0.005 0.0001 0.0001" /></contact><actuator><general site="virtbumblebee_hooked_0_cog" name="virtbumblebee_hooked_0_actr0" gear=" 0 0 1 0 0 0" ctrllimited="true" ctrlrange="0 67.2" /><general site="virtbumblebee_hooked_0_cog" name="virtbumblebee_hooked_0_actr1" gear=" 0 0 0 1 0 0" ctrllimited="true" ctrlrange="-6 6" /><general site="virtbumblebee_hooked_0_cog" name="virtbumblebee_hooked_0_actr2" gear=" 0 0 0 0 1 0" ctrllimited="true" ctrlrange="-6 6" /><general site="virtbumblebee_hooked_0_cog" name="virtbumblebee_hooked_0_actr3" gear=" 0 0 0 0 0 1" ctrllimited="true" ctrlrange="-1.5 1.5" /><velocity name="virtfleet1tenth_0_wheelrl_actr" joint="virtfleet1tenth_0_wheelrl" /><velocity name="virtfleet1tenth_0_wheelrr_actr" joint="virtfleet1tenth_0_wheelrr" /><position name="virtfleet1tenth_0_wheelfl_actr_steer" joint="virtfleet1tenth_0_wheelfl_steer" /><position name="virtfleet1tenth_0_wheelfr_actr_steer" joint="virtfleet1tenth_0_wheelfr_steer" /></actuator><sensor><gyro site="virtbumblebee_hooked_0_cog" name="virtbumblebee_hooked_0_sensor0" /></sensor></mujoco>