<mujoco><include file="../xml_models/scene.xml" /><worldbody><body name="car0" pos="1.9133065 -0.23948243 0" quat="-0.009944528341293335 -0.02588188648223877 0.01663799025118351 0.9994770884513855" mocap="true"><geom name="car0" type="box" size=".1016 .10113 .02" pos="-.06 0 0" rgba=".2 .2 .9 1.0" /><geom name="car0_front" type="box" size=".07 .06 .02" pos=".10113 0 0" rgba=".2 .2 .9 1.0" /><geom name="car_pole" type="cylinder" size="0.01 0.5" pos="-.2135 0 0.5" rgba="0.3 0.3 0.3 1.0" /><body name="car0_wheelfl" quat="1 0 0 0"><joint name="car0_wheelfl" type="hinge" pos="0.16113 .122385 0" axis="0 1 0" /><geom name="car0_wheelfl" type="cylinder" size=".052388 .022225" pos="0.16113 .122385 0" material="material_check" euler="1.571 0 0" /></body><body name="car0_wheelrl" quat="1 0 0 0"><joint name="car0_wheelrl" type="hinge" pos="-0.16113 .122385 0" axis="0 1 0" /><geom name="car0_wheelrl" type="cylinder" size=".052388 .022225" pos="-0.16113 .122385 0" material="material_check" euler="1.571 0 0" /></body><body name="car0_wheelfr" quat="1 0 0 0"><joint name="car0_wheelfr" type="hinge" pos="0.16113 -.122385 0" axis="0 1 0" /><geom name="car0_wheelfr" type="cylinder" size=".052388 .022225" pos="0.16113 -.122385 0" material="material_check" euler="1.571 0 0" /></body><body name="car0_wheelrr" quat="1 0 0 0"><joint name="car0_wheelrr" type="hinge" pos="-0.16113 -.122385 0" axis="0 1 0" /><geom name="car0_wheelrr" type="cylinder" size=".052388 .022225" pos="-0.16113 -.122385 0" material="material_check" euler="1.571 0 0" /></body></body><body name="obst0" pos="0.29732436 -0.16997443 0" quat="0.3826834 0 0 0.9238795"><geom class="pole_top" /><geom class="pole_bottom1" /><geom class="pole_bottom2" /></body><body name="obst1" pos="-0.27175057 -0.23468345 0" quat="0.3826834 0 0 0.9238795"><geom class="pole_top" /><geom class="pole_bottom1" /><geom class="pole_bottom2" /></body><body name="obst2" pos="-0.07596505 0.42926958 0" quat="0.3826834 0 0 0.9238795"><geom class="pole_top" /><geom class="pole_bottom1" /><geom class="pole_bottom2" /></body></worldbody><actuator /><sensor /></mujoco>