<mujoco>
	<include file="../xml_models/scene.xml" />
	<worldbody>
		<body name="hospital" pos="-1.0894159 1.2964101 0" quat="1 0 0 0">
			<geom name="hospital" type="box" pos="0 0 0.445" size="0.1275 0.13 0.445" material="mat-hospital" />
		</body>
		<body name="tall_landing_zone" pos="-0.015748141 0.017407836 0" quat="1 0 0 0">
			<geom name="tall_landing_zone" type="box" pos="0 0 0.0925" size="0.105 0.105 0.0925" rgba="0.8 0.8 0.8 1.0" material="mat-sztaki" />
		</body>
		<body name="post_office" pos="1.0914855 -1.100901 0" quat="1 0 0 0">
			<geom name="post_office" type="box" pos="0 0 0.205" size="0.1275 0.1275 0.205" material="mat-post_office" />
		</body>
		<geom name="airport" pos="1.11125 1.0081892 0.01" quat="1 0 0 0" size="0.105 0.105 .05" type="plane" material="mat-airport" />
		<body name="lz_cf10" pos="-0.9774649 -1.212606 0" quat="1 0 0 0">
			<geom class="landing_zone" />
		</body>
		<body name="realdrone_0" pos="-0.9774649 -1.212606 0.033930637" quat="-0.8685286045074463 -0.02548149973154068 -0.017981912940740585 -0.49465683102607727">
			<inertial pos="0 0 0" diaginertia="1.4e-5 1.4e-5 2.17e-5" mass="0.028" />
			<joint name="realdrone_0" type="free" />
			<geom name="realdrone_0_body" type="mesh" mesh="drone_body" rgba="0.2 0.2 0.85 1.0" />
			<geom name="realdrone_0_4_motormounts" type="mesh" mesh="drone_4_motormounts" rgba="0.2 0.2 0.85 1.0" />
			<geom name="realdrone_0_4_motors" type="mesh" mesh="drone_4_motors" rgba="0.2 0.2 0.85 1.0" />
			<site name="realdrone_0_cog" pos="0 0 0" />
			<body name="realdrone_0_prop1">
				<joint name="realdrone_0_prop1" axis="0 0 1" pos="0.047 0.047 0.032" />
				<geom name="realdrone_0_prop1" type="mesh" mesh="drone_ccw_prop" pos="0.047 0.047 0.032" rgba="0.1 0.1 0.1 1.0" euler="0 0 -0.785" />
			</body>
			<body name="realdrone_0_prop2">
				<joint name="realdrone_0_prop2" axis="0 0 1" pos="-0.047 -0.047 0.032" />
				<geom name="realdrone_0_prop2" type="mesh" mesh="drone_ccw_prop" pos="-0.047 -0.047 0.032" rgba="0.1 0.1 0.1 1.0" euler="0 0 -0.785" />
			</body>
			<body name="realdrone_0_prop3">
				<joint name="realdrone_0_prop3" axis="0 0 1" pos="-0.047 0.047 0.032" />
				<geom name="realdrone_0_prop3" type="mesh" mesh="drone_cw_prop" pos="-0.047 0.047 0.032" rgba="0.1 0.1 0.1 1.0" euler="0 0 0.785" />
			</body>
			<body name="realdrone_0_prop4">
				<joint name="realdrone_0_prop4" axis="0 0 1" pos="0.047 -0.047 0.032" />
				<geom name="realdrone_0_prop4" type="mesh" mesh="drone_cw_prop" pos="0.047 -0.047 0.032" rgba="0.1 0.1 0.1 1.0" euler="0 0 0.785" />
			</body>
		</body>
		<body name="lz_cf2" pos="-1.3800427 -0.29468468 0" quat="1 0 0 0">
			<geom class="landing_zone" />
		</body>
		<body name="realdrone_1" pos="-1.3800427 -0.29468468 0.008406427" quat="-0.9970715045928955 -0.033101629465818405 -0.018997838720679283 0.06627034395933151">
			<inertial pos="0 0 0" diaginertia="1.4e-5 1.4e-5 2.17e-5" mass="0.028" />
			<joint name="realdrone_1" type="free" />
			<geom name="realdrone_1_body" type="mesh" mesh="drone_body" rgba="0.2 0.2 0.85 1.0" />
			<geom name="realdrone_1_4_motormounts" type="mesh" mesh="drone_4_motormounts" rgba="0.2 0.2 0.85 1.0" />
			<geom name="realdrone_1_4_motors" type="mesh" mesh="drone_4_motors" rgba="0.2 0.2 0.85 1.0" />
			<site name="realdrone_1_cog" pos="0 0 0" />
			<body name="realdrone_1_prop1">
				<joint name="realdrone_1_prop1" axis="0 0 1" pos="0.047 0.047 0.032" />
				<geom name="realdrone_1_prop1" type="mesh" mesh="drone_ccw_prop" pos="0.047 0.047 0.032" rgba="0.1 0.1 0.1 1.0" euler="0 0 -0.785" />
			</body>
			<body name="realdrone_1_prop2">
				<joint name="realdrone_1_prop2" axis="0 0 1" pos="-0.047 -0.047 0.032" />
				<geom name="realdrone_1_prop2" type="mesh" mesh="drone_ccw_prop" pos="-0.047 -0.047 0.032" rgba="0.1 0.1 0.1 1.0" euler="0 0 -0.785" />
			</body>
			<body name="realdrone_1_prop3">
				<joint name="realdrone_1_prop3" axis="0 0 1" pos="-0.047 0.047 0.032" />
				<geom name="realdrone_1_prop3" type="mesh" mesh="drone_cw_prop" pos="-0.047 0.047 0.032" rgba="0.1 0.1 0.1 1.0" euler="0 0 0.785" />
			</body>
			<body name="realdrone_1_prop4">
				<joint name="realdrone_1_prop4" axis="0 0 1" pos="0.047 -0.047 0.032" />
				<geom name="realdrone_1_prop4" type="mesh" mesh="drone_cw_prop" pos="0.047 -0.047 0.032" rgba="0.1 0.1 0.1 1.0" euler="0 0 0.785" />
			</body>
		</body>
		<body name="lz_cf4" pos="-1.35337 -0.6283787 0" quat="1 0 0 0">
			<geom class="landing_zone" />
		</body>
		<body name="realdrone_2" pos="-1.35337 -0.6283787 0.011032723" quat="0.9904438257217407 -0.025728711858391762 -0.009102720767259598 0.13518959283828735">
			<inertial pos="0 0 0" diaginertia="1.4e-5 1.4e-5 2.17e-5" mass="0.028" />
			<joint name="realdrone_2" type="free" />
			<geom name="realdrone_2_body" type="mesh" mesh="drone_body" rgba="0.2 0.2 0.85 1.0" />
			<geom name="realdrone_2_4_motormounts" type="mesh" mesh="drone_4_motormounts" rgba="0.2 0.2 0.85 1.0" />
			<geom name="realdrone_2_4_motors" type="mesh" mesh="drone_4_motors" rgba="0.2 0.2 0.85 1.0" />
			<site name="realdrone_2_cog" pos="0 0 0" />
			<body name="realdrone_2_prop1">
				<joint name="realdrone_2_prop1" axis="0 0 1" pos="0.047 0.047 0.032" />
				<geom name="realdrone_2_prop1" type="mesh" mesh="drone_ccw_prop" pos="0.047 0.047 0.032" rgba="0.1 0.1 0.1 1.0" euler="0 0 -0.785" />
			</body>
			<body name="realdrone_2_prop2">
				<joint name="realdrone_2_prop2" axis="0 0 1" pos="-0.047 -0.047 0.032" />
				<geom name="realdrone_2_prop2" type="mesh" mesh="drone_ccw_prop" pos="-0.047 -0.047 0.032" rgba="0.1 0.1 0.1 1.0" euler="0 0 -0.785" />
			</body>
			<body name="realdrone_2_prop3">
				<joint name="realdrone_2_prop3" axis="0 0 1" pos="-0.047 0.047 0.032" />
				<geom name="realdrone_2_prop3" type="mesh" mesh="drone_cw_prop" pos="-0.047 0.047 0.032" rgba="0.1 0.1 0.1 1.0" euler="0 0 0.785" />
			</body>
			<body name="realdrone_2_prop4">
				<joint name="realdrone_2_prop4" axis="0 0 1" pos="0.047 -0.047 0.032" />
				<geom name="realdrone_2_prop4" type="mesh" mesh="drone_cw_prop" pos="0.047 -0.047 0.032" rgba="0.1 0.1 0.1 1.0" euler="0 0 0.785" />
			</body>
		</body>
		<body name="lz_cf5" pos="-1.199099 -0.98191947 0" quat="1 0 0 0">
			<geom class="landing_zone" />
		</body>
		<body name="realdrone_3" pos="-1.199099 -0.98191947 0.02503483" quat="0.9479548335075378 -0.041796933859586716 0.04655821621417999 0.31219714879989624">
			<inertial pos="0 0 0" diaginertia="1.4e-5 1.4e-5 2.17e-5" mass="0.028" />
			<joint name="realdrone_3" type="free" />
			<geom name="realdrone_3_body" type="mesh" mesh="drone_body" rgba="0.2 0.2 0.85 1.0" />
			<geom name="realdrone_3_4_motormounts" type="mesh" mesh="drone_4_motormounts" rgba="0.2 0.2 0.85 1.0" />
			<geom name="realdrone_3_4_motors" type="mesh" mesh="drone_4_motors" rgba="0.2 0.2 0.85 1.0" />
			<site name="realdrone_3_cog" pos="0 0 0" />
			<body name="realdrone_3_prop1">
				<joint name="realdrone_3_prop1" axis="0 0 1" pos="0.047 0.047 0.032" />
				<geom name="realdrone_3_prop1" type="mesh" mesh="drone_ccw_prop" pos="0.047 0.047 0.032" rgba="0.1 0.1 0.1 1.0" euler="0 0 -0.785" />
			</body>
			<body name="realdrone_3_prop2">
				<joint name="realdrone_3_prop2" axis="0 0 1" pos="-0.047 -0.047 0.032" />
				<geom name="realdrone_3_prop2" type="mesh" mesh="drone_ccw_prop" pos="-0.047 -0.047 0.032" rgba="0.1 0.1 0.1 1.0" euler="0 0 -0.785" />
			</body>
			<body name="realdrone_3_prop3">
				<joint name="realdrone_3_prop3" axis="0 0 1" pos="-0.047 0.047 0.032" />
				<geom name="realdrone_3_prop3" type="mesh" mesh="drone_cw_prop" pos="-0.047 0.047 0.032" rgba="0.1 0.1 0.1 1.0" euler="0 0 0.785" />
			</body>
			<body name="realdrone_3_prop4">
				<joint name="realdrone_3_prop4" axis="0 0 1" pos="0.047 -0.047 0.032" />
				<geom name="realdrone_3_prop4" type="mesh" mesh="drone_cw_prop" pos="0.047 -0.047 0.032" rgba="0.1 0.1 0.1 1.0" euler="0 0 0.785" />
			</body>
		</body>
		<body name="obst0" pos="-0.007762169 -0.2687551 0" quat="-0.4809565246105194 -0.007430885918438435 -0.018251772969961166 -0.8765230178833008">
			<geom class="pole_top" />
			<geom class="pole_bottom1" />
			<geom class="pole_bottom2" />
		</body>
		<body name="obst1" pos="-0.071768485 0.44808042 0" quat="-0.7313159704208374 0.007468543481081724 0.013025025837123394 0.6818735003471375">
			<geom class="pole_top" />
			<geom class="pole_bottom1" />
			<geom class="pole_bottom2" />
		</body>
		<body name="obst2" pos="0.21443598 0.3342193 0" quat="-0.5956709384918213 0.015845857560634613 0.023386972025036812 0.8027316927909851">
			<geom class="pole_top" />
			<geom class="pole_bottom1" />
			<geom class="pole_bottom2" />
		</body>
	</worldbody>
	<actuator>
		<general site="realdrone_0_cog" gear=" 0 0 1 0 0 0" ctrllimited="true" ctrlrange="0 0.64" />
		<general site="realdrone_0_cog" gear=" 0 0 0 1 0 0" ctrllimited="true" ctrlrange="-0.01 0.01" />
		<general site="realdrone_0_cog" gear=" 0 0 0 0 1 0" ctrllimited="true" ctrlrange="-0.01 0.01" />
		<general site="realdrone_0_cog" gear=" 0 0 0 0 0 1" ctrllimited="true" ctrlrange="-0.01 0.01" />
		<general site="realdrone_1_cog" gear=" 0 0 1 0 0 0" ctrllimited="true" ctrlrange="0 0.64" />
		<general site="realdrone_1_cog" gear=" 0 0 0 1 0 0" ctrllimited="true" ctrlrange="-0.01 0.01" />
		<general site="realdrone_1_cog" gear=" 0 0 0 0 1 0" ctrllimited="true" ctrlrange="-0.01 0.01" />
		<general site="realdrone_1_cog" gear=" 0 0 0 0 0 1" ctrllimited="true" ctrlrange="-0.01 0.01" />
		<general site="realdrone_2_cog" gear=" 0 0 1 0 0 0" ctrllimited="true" ctrlrange="0 0.64" />
		<general site="realdrone_2_cog" gear=" 0 0 0 1 0 0" ctrllimited="true" ctrlrange="-0.01 0.01" />
		<general site="realdrone_2_cog" gear=" 0 0 0 0 1 0" ctrllimited="true" ctrlrange="-0.01 0.01" />
		<general site="realdrone_2_cog" gear=" 0 0 0 0 0 1" ctrllimited="true" ctrlrange="-0.01 0.01" />
		<general site="realdrone_3_cog" gear=" 0 0 1 0 0 0" ctrllimited="true" ctrlrange="0 0.64" />
		<general site="realdrone_3_cog" gear=" 0 0 0 1 0 0" ctrllimited="true" ctrlrange="-0.01 0.01" />
		<general site="realdrone_3_cog" gear=" 0 0 0 0 1 0" ctrllimited="true" ctrlrange="-0.01 0.01" />
		<general site="realdrone_3_cog" gear=" 0 0 0 0 0 1" ctrllimited="true" ctrlrange="-0.01 0.01" />
	</actuator>
	<sensor>
		<gyro site="realdrone_0_cog" />
		<gyro site="realdrone_1_cog" />
		<gyro site="realdrone_2_cog" />
		<gyro site="realdrone_3_cog" />
	</sensor>
</mujoco>