<mujoco><include file="../xml_models/scene.xml" /><worldbody><body name="car0" pos="0.89420223 0.84136254 0" quat="-0.37623974680900574 0.026862265542149544 -0.011859125457704067 -0.926056981086731" mocap="true"><geom name="car0" type="box" size=".1 .13 .02" pos="-.07 0 0" rgba=".2 .2 .9 1.0" /><geom name="car0_front" type="box" size=".07 .07 .02" pos=".13 0 0" rgba=".2 .2 .9 1.0" /><geom name="car_pole" type="cylinder" size="0.01 0.5" pos="-.2 0 0.5" rgba="0.3 0.3 0.3 1.0" /><body name="car0_wheelfl" pos="0.2 .12 0" quat="1 0 0 0"><joint name="car0_wheelfl" type="hinge" axis="0 1 0" /><geom name="car0_wheelfl" type="cylinder" size=".06 .02" material="material_check" euler="1.571 0 0" /></body><body name="car0_wheelrl" pos="-0.2 .12 0" quat="1 0 0 0"><joint name="car0_wheelrl" type="hinge" axis="0 1 0" /><geom name="car0_wheelrl" type="cylinder" size=".06 .02" material="material_check" euler="1.571 0 0" /></body><body name="car0_wheelfr" pos="0.2 -.12 0" quat="1 0 0 0"><joint name="car0_wheelfr" type="hinge" axis="0 1 0" /><geom name="car0_wheelfr" type="cylinder" size=".06 .02" material="material_check" euler="1.571 0 0" /></body><body name="car0_wheelrr" pos="-0.2 -.12 0" quat="1 0 0 0"><joint name="car0_wheelrr" type="hinge" axis="0 1 0" /><geom name="car0_wheelrr" type="cylinder" size=".06 .02" material="material_check" euler="1.571 0 0" /></body></body></worldbody><actuator /><sensor /></mujoco>