<mujoco><include file="../xml_models/scene.xml" /><worldbody><body name="virtcrazyflie_0" pos="1 1 1" quat="1 0 0 0"><inertial pos="0 0 0" diaginertia="1.4e-5 1.4e-5 2.17e-5" mass="0.028" /><joint name="virtcrazyflie_0" type="free" /><geom name="virtcrazyflie_0_body" type="mesh" mesh="drone_body" rgba="0.85 0.2 0.2 1.0" /><geom name="virtcrazyflie_0_4_motormounts" type="mesh" mesh="drone_4_motormounts" rgba="0.85 0.2 0.2 1.0" /><geom name="virtcrazyflie_0_4_motors" type="mesh" mesh="drone_4_motors" rgba="0.85 0.2 0.2 1.0" /><site name="virtcrazyflie_0_cog" pos="0 0 0" /><body name="virtcrazyflie_0_prop1"><joint name="virtcrazyflie_0_prop1" axis="0 0 1" pos="0.047 0.047 0.032" /><geom name="virtcrazyflie_0_prop1" type="mesh" mesh="drone_ccw_prop" mass="0.00001" pos="0.047 0.047 0.032" rgba="0.1 0.1 0.1 1.0" euler="0 0 -0.785" /></body><body name="virtcrazyflie_0_prop2"><joint name="virtcrazyflie_0_prop2" axis="0 0 1" pos="-0.047 -0.047 0.032" /><geom name="virtcrazyflie_0_prop2" type="mesh" mesh="drone_ccw_prop" mass="0.00001" pos="-0.047 -0.047 0.032" rgba="0.1 0.1 0.1 1.0" euler="0 0 -0.785" /></body><body name="virtcrazyflie_0_prop3"><joint name="virtcrazyflie_0_prop3" axis="0 0 1" pos="-0.047 0.047 0.032" /><geom name="virtcrazyflie_0_prop3" type="mesh" mesh="drone_cw_prop" mass="0.00001" pos="-0.047 0.047 0.032" rgba="0.1 0.1 0.1 1.0" euler="0 0 0.785" /></body><body name="virtcrazyflie_0_prop4"><joint name="virtcrazyflie_0_prop4" axis="0 0 1" pos="0.047 -0.047 0.032" /><geom name="virtcrazyflie_0_prop4" type="mesh" mesh="drone_cw_prop" mass="0.00001" pos="0.047 -0.047 0.032" rgba="0.1 0.1 0.1 1.0" euler="0 0 0.785" /></body></body><body name="realcrazyflie_0" pos="1 0 1" quat="1 0 0 0" mocap="true"><geom name="realcrazyflie_0_body" type="mesh" mesh="drone_body" rgba="0.2 0.2 0.85 1.0" /><geom name="realcrazyflie_0_4_motormounts" type="mesh" mesh="drone_4_motormounts" rgba="0.2 0.2 0.85 1.0" /><geom name="realcrazyflie_0_4_motors" type="mesh" mesh="drone_4_motors" rgba="0.2 0.2 0.85 1.0" /></body><body name="realcrazyflie_0_prop1" pos="0.047 0.047 0.032" quat="1 0 0 0" mocap="true"><geom name="realcrazyflie_0_prop1" type="mesh" mesh="drone_ccw_prop" pos="0.047 0.047 0.032" rgba="0.1 0.1 0.1 1.0" euler="0 0 -0.785" /></body><body name="realcrazyflie_0_prop2" pos="-0.047 -0.047 0.032" quat="1 0 0 0" mocap="true"><geom name="realcrazyflie_0_prop2" type="mesh" mesh="drone_ccw_prop" pos="-0.047 -0.047 0.032" rgba="0.1 0.1 0.1 1.0" euler="0 0 -0.785" /></body><body name="realcrazyflie_0_prop3" pos="-0.047 0.047 0.032" quat="1 0 0 0" mocap="true"><geom name="realcrazyflie_0_prop3" type="mesh" mesh="drone_cw_prop" pos="-0.047 0.047 0.032" rgba="0.1 0.1 0.1 1.0" euler="0 0 -0.785" /></body><body name="realcrazyflie_0_prop4" pos="0.047 -0.047 0.032" quat="1 0 0 0" mocap="true"><geom name="realcrazyflie_0_prop4" type="mesh" mesh="drone_cw_prop" pos="0.047 -0.047 0.032" rgba="0.1 0.1 0.1 1.0" euler="0 0 -0.785" /></body><body name="realcrazyflie_1" pos="1 1 0" quat="1 0 0 0" mocap="true"><geom name="realcrazyflie_1_body" type="mesh" mesh="drone_body" rgba="0.2 0.2 0.85 1.0" /><geom name="realcrazyflie_1_4_motormounts" type="mesh" mesh="drone_4_motormounts" rgba="0.2 0.2 0.85 1.0" /><geom name="realcrazyflie_1_4_motors" type="mesh" mesh="drone_4_motors" rgba="0.2 0.2 0.85 1.0" /></body><body name="realcrazyflie_1_prop1" pos="0.047 0.047 0.032" quat="1 0 0 0" mocap="true"><geom name="realcrazyflie_1_prop1" type="mesh" mesh="drone_ccw_prop" pos="0.047 0.047 0.032" rgba="0.1 0.1 0.1 1.0" euler="0 0 -0.785" /></body><body name="realcrazyflie_1_prop2" pos="-0.047 -0.047 0.032" quat="1 0 0 0" mocap="true"><geom name="realcrazyflie_1_prop2" type="mesh" mesh="drone_ccw_prop" pos="-0.047 -0.047 0.032" rgba="0.1 0.1 0.1 1.0" euler="0 0 -0.785" /></body><body name="realcrazyflie_1_prop3" pos="-0.047 0.047 0.032" quat="1 0 0 0" mocap="true"><geom name="realcrazyflie_1_prop3" type="mesh" mesh="drone_cw_prop" pos="-0.047 0.047 0.032" rgba="0.1 0.1 0.1 1.0" euler="0 0 -0.785" /></body><body name="realcrazyflie_1_prop4" pos="0.047 -0.047 0.032" quat="1 0 0 0" mocap="true"><geom name="realcrazyflie_1_prop4" type="mesh" mesh="drone_cw_prop" pos="0.047 -0.047 0.032" rgba="0.1 0.1 0.1 1.0" euler="0 0 -0.785" /></body></worldbody><actuator><general site="virtcrazyflie_0_cog" name="virtcrazyflie_0_actr0" gear=" 0 0 1 0 0 0" ctrllimited="true" ctrlrange="0 0.64" /><general site="virtcrazyflie_0_cog" name="virtcrazyflie_0_actr1" gear=" 0 0 0 1 0 0" ctrllimited="true" ctrlrange="-0.01 0.01" /><general site="virtcrazyflie_0_cog" name="virtcrazyflie_0_actr2" gear=" 0 0 0 0 1 0" ctrllimited="true" ctrlrange="-0.01 0.01" /><general site="virtcrazyflie_0_cog" name="virtcrazyflie_0_actr3" gear=" 0 0 0 0 0 1" ctrllimited="true" ctrlrange="-0.01 0.01" /></actuator><sensor><gyro site="virtcrazyflie_0_cog" name="virtcrazyflie_0_sensor0" /></sensor></mujoco>