<mujoco><include file="scene.xml" /><worldbody><body name="virtbumblebee_hooked_0" pos="1 1 1" quat="1 0 0 0"><inertial pos="0 0 0" diaginertia="1.5e-3 1.45e-3 2.66e-3" mass="0.407" /><joint name="virtbumblebee_hooked_0" type="free" /><geom name="virtbumblebee_hooked_0_body" pos="0.0132 0 0" type="mesh" quat="-0.7071067811865475 -0.0 0.0 0.7071067811865476" mesh="drone_body_large" rgba="0.85 0.2 0.2 1.0" /><site name="virtbumblebee_hooked_0_cog" pos="0 0 0" /><body name="virtbumblebee_hooked_0_rod" pos="0 0 0"><geom type="cylinder" fromto="0 0 0  0 0 -0.4" size="0.0025" mass="0.00" /><site name="virtbumblebee_hooked_0_rod_end" pos="0 0 -0.4" type="sphere" size="0.002" /><joint name="virtbumblebee_hooked_0_hook_y" axis="0 1 0" pos="0 0 0" damping="0.001" /><joint name="virtbumblebee_hooked_0_hook_x" axis="1 0 0" pos="0 0 0" damping="0.001" /><body name="virtbumblebee_hooked_0_hook" pos="0 0 -0.4" euler="0 3.141592 -1.57"><geom type="capsule" pos="0 0 0.02" size="0.002 0.02" mass="0.02" /><geom type="capsule" pos="0 0.01299 0.0475" euler="-1.0472 0 0" size="0.005 0.018" mass="0.0001" /><geom type="capsule" pos="0 0.02598 0.07" euler="0 0 0" size="0.005 0.018" mass="0.0001" /><geom type="capsule" pos="0 0.01299 0.0925" euler="1.0472 0 0" size="0.005 0.018" mass="0.0001" /><geom type="capsule" pos="0 -0.01299 0.0925" euler="2.0944 0 0" size="0.005 0.018" mass="0.0001" /></body></body><body name="virtbumblebee_hooked_0_prop1"><joint name="virtbumblebee_hooked_0_prop1" axis="0 0 1" pos="-0.074 0.087 0.036" /><geom name="virtbumblebee_hooked_0_prop1" type="mesh" mesh="drone_ccw_prop_large" mass="0.00001" pos="-0.074 0.087 0.036" rgba="0.1 0.02 0.5 1.0" /></body><body name="virtbumblebee_hooked_0_prop2"><joint name="virtbumblebee_hooked_0_prop2" axis="0 0 1" pos="0.091 -0.087 0.036" /><geom name="virtbumblebee_hooked_0_prop2" type="mesh" mesh="drone_ccw_prop_large" mass="0.00001" pos="0.091 -0.087 0.036" rgba="0.1 0.02 0.5 1.0" /></body><body name="virtbumblebee_hooked_0_prop3"><joint name="virtbumblebee_hooked_0_prop3" axis="0 0 1" pos="0.091 0.087 0.036" /><geom name="virtbumblebee_hooked_0_prop3" type="mesh" mesh="drone_cw_prop_large" mass="0.00001" pos="0.091 0.087 0.036" rgba="0.1 0.02 0.5 1.0" /></body><body name="virtbumblebee_hooked_0_prop4"><joint name="virtbumblebee_hooked_0_prop4" axis="0 0 1" pos="-0.074 -0.087 0.036" /><geom name="virtbumblebee_hooked_0_prop4" type="mesh" mesh="drone_cw_prop_large" mass="0.00001" pos="-0.074 -0.087 0.036" rgba="0.1 0.02 0.5 1.0" /></body></body><body name="virtfleet1tenth_0" pos="-0.5 1 0.2" quat="1 0 0 0"><inertial pos="0 0 0" diaginertia=".05 .05 .08" mass="3.0" /><joint name="virtfleet1tenth_0" type="free" /><site name="virtfleet1tenth_0_cog" pos="0 0 0" /><geom name="virtfleet1tenth_0_chassis_b" type="box" size=".10113 .1016 .02" pos="-.06 0 0" rgba="0.85 0.2 0.2 1.0" /><geom name="virtfleet1tenth_0_chassis_f" type="box" size=".06 .07 .02" pos=".10113 0 0" rgba="0.85 0.2 0.2 1.0" /><geom name="virtfleet1tenth_0_front" type="box" size=".052388 .02 .02" pos=".2135 0 0" rgba="0.85 0.2 0.2 1.0" /><geom name="virtfleet1tenth_0_back" type="box" size=".052388 .02 .02" pos="-.2135 0 0" rgba="0.85 0.2 0.2 1.0" /><geom name="virtfleet1tenth_0_front_bumper" type="box" size=".005 .09 .02" pos=".265888 0 0.02" rgba="0.85 0.2 0.2 1.0" /><geom name="virtfleet1tenth_0_back_bumper" type="box" size=".005 .08 .02" pos="-.265888 0 0.02" rgba="0.85 0.2 0.2 1.0" /><geom name="virtfleet1tenth_0_number" type="cylinder" size=".01984 .03" pos=".12 0 .05" rgba="0.1 0.1 0.1 1.0" /><geom name="virtfleet1tenth_0_camera" type="box" size=".012 .06 0.02" pos=".18 0 .08" /><geom name="virtfleet1tenth_0_camera_holder" type="box" size=".012 .008 .02" pos=".18 0 .04" /><geom name="virtfleet1tenth_0_circuits" type="box" size=".08 .06 .03" pos="-.05 0 .05" rgba="0.85 0.2 0.2 1.0" /><geom name="virtfleet1tenth_0_antennal" type="box" size=".007 .004 .06" pos="-.16 -.01 .105" euler="0.2 0 0" rgba=".1 .1 .1 1.0" /><geom name="virtfleet1tenth_0_antennar" type="box" size=".007 .004 .06" pos="-.16 .01 .105" euler="-0.2 0 0" rgba=".1 .1 .1 1.0" /><geom name="virtfleet1tenth_0_antenna_holder" type="box" size=".008 .008 .02" pos="-.16 0 .04" rgba=".1 .1 .1 1.0" /><body name="virtfleet1tenth_0_wheelfl" quat="1 0 0 0"><joint name="virtfleet1tenth_0_wheelfl_steer" type="hinge" pos="0.16113 .10016 0" limited="true" frictionloss="0.2" damping="0.2" armature="0.001" range="-0.6 0.6" axis="0 0 1" /><joint name="virtfleet1tenth_0_wheelfl" type="hinge" pos="0.16113 .122385 0" axis="0 1 0" frictionloss="0.01" damping="0.00001" armature="0.05" limited="false" /><geom name="virtfleet1tenth_0_wheelfl" type="cylinder" size=".052388 .022225" pos="0.16113 .122385 0" mass="0.1" material="material_check" euler="1.571 0 0" /></body><body name="virtfleet1tenth_0_wheelrl" quat="1 0 0 0"><joint name="virtfleet1tenth_0_wheelrl" type="hinge" pos="-0.16113 .122385 0" axis="0 1 0" frictionloss="0.01" damping="0.00001" armature="0.05" limited="false" /><geom name="virtfleet1tenth_0_wheelrl" type="cylinder" size=".052388 .022225" pos="-0.16113 .122385 0" mass="0.1" material="material_check" euler="1.571 0 0" /></body><body name="virtfleet1tenth_0_wheelfr" quat="1 0 0 0"><joint name="virtfleet1tenth_0_wheelfr_steer" type="hinge" pos="0.16113 -.10016 0" limited="true" frictionloss="0.2" damping="0.2" armature="0.001" range="-0.6 0.6" axis="0 0 1" /><joint name="virtfleet1tenth_0_wheelfr" type="hinge" pos="0.16113 -.122385 0" axis="0 1 0" frictionloss="0.01" damping="0.00001" armature="0.05" limited="false" /><geom name="virtfleet1tenth_0_wheelfr" type="cylinder" size=".052388 .022225" pos="0.16113 -.122385 0" mass="0.1" material="material_check" euler="1.571 0 0" /></body><body name="virtfleet1tenth_0_wheelrr" quat="1 0 0 0"><joint name="virtfleet1tenth_0_wheelrr" type="hinge" pos="-0.16113 -.122385 0" axis="0 1 0" frictionloss="0.01" damping="0.00001" armature="0.05" limited="false" /><geom name="virtfleet1tenth_0_wheelrr" type="cylinder" size=".052388 .022225" pos="-0.16113 -.122385 0" mass="0.1" material="material_check" euler="1.571 0 0" /></body></body></worldbody><contact><pair geom1="virtfleet1tenth_0_wheelfl" geom2="roundabout" condim="6" friction="2.5 2.5 .009 .0001 .0001" /><pair geom1="virtfleet1tenth_0_wheelfr" geom2="roundabout" condim="6" friction="2.5 2.5 .009 .0001 .0001" /><pair geom1="virtfleet1tenth_0_wheelrl" geom2="roundabout" condim="6" friction="2.5 2.5 .009 .0001 .0001" /><pair geom1="virtfleet1tenth_0_wheelrr" geom2="roundabout" condim="6" friction="2.5 2.5 .009 .0001 .0001" /></contact><actuator><general site="virtbumblebee_hooked_0_cog" name="virtbumblebee_hooked_0_actr0" gear=" 0 0 1 0 0 0" ctrllimited="true" ctrlrange="0 67.2" /><general site="virtbumblebee_hooked_0_cog" name="virtbumblebee_hooked_0_actr1" gear=" 0 0 0 1 0 0" ctrllimited="true" ctrlrange="-6 6" /><general site="virtbumblebee_hooked_0_cog" name="virtbumblebee_hooked_0_actr2" gear=" 0 0 0 0 1 0" ctrllimited="true" ctrlrange="-6 6" /><general site="virtbumblebee_hooked_0_cog" name="virtbumblebee_hooked_0_actr3" gear=" 0 0 0 0 0 1" ctrllimited="true" ctrlrange="-1.5 1.5" /><motor name="virtfleet1tenth_0_wheelfl_actr" joint="virtfleet1tenth_0_wheelfl" /><motor name="virtfleet1tenth_0_wheelfr_actr" joint="virtfleet1tenth_0_wheelfr" /><motor name="virtfleet1tenth_0_wheelrl_actr" joint="virtfleet1tenth_0_wheelrl" /><motor name="virtfleet1tenth_0_wheelrr_actr" joint="virtfleet1tenth_0_wheelrr" /><position forcelimited="true" forcerange="-5 5" name="virtfleet1tenth_0_wheelfl_actr_steer" joint="virtfleet1tenth_0_wheelfl_steer" kp="15" /><position forcelimited="true" forcerange="-5 5" name="virtfleet1tenth_0_wheelfr_actr_steer" joint="virtfleet1tenth_0_wheelfr_steer" kp="15" /></actuator><sensor><gyro site="virtbumblebee_hooked_0_rod_end" name="virtbumblebee_hooked_0_hook_gyro" /><framequat objtype="site" objname="virtbumblebee_hooked_0_rod_end" name="virtbumblebee_hooked_0_hook_orimeter" /><gyro site="virtbumblebee_hooked_0_cog" name="virtbumblebee_hooked_0_gyro" /><velocimeter site="virtbumblebee_hooked_0_cog" name="virtbumblebee_hooked_0_velocimeter" /><framepos objtype="site" objname="virtbumblebee_hooked_0_cog" name="virtbumblebee_hooked_0_posimeter" /><framequat objtype="site" objname="virtbumblebee_hooked_0_cog" name="virtbumblebee_hooked_0_orimeter" /><gyro site="virtfleet1tenth_0_cog" name="virtfleet1tenth_0_gyro" /><velocimeter site="virtfleet1tenth_0_cog" name="virtfleet1tenth_0_velocimeter" /><framepos objtype="site" objname="virtfleet1tenth_0_cog" name="virtfleet1tenth_0_posimeter" /><framequat objtype="site" objname="virtfleet1tenth_0_cog" name="virtfleet1tenth_0_orimeter" /></sensor></mujoco>