<mujoco><include file="../xml_models/scene.xml" /><worldbody><body name="car0" pos="1.1651154 -0.15161116 0" quat="-0.7966912984848022 0.018741179257631302 -0.02044142410159111 -0.6037499308586121" mocap="true"><geom name="car0" type="box" size=".1 .13 .02" pos="-.07 0 0" rgba=".2 .2 .9 1.0" /><geom name="car0_front" type="box" size=".07 .07 .02" pos=".13 0 0" rgba=".2 .2 .9 1.0" /><body name="car0_wheelfl" pos="0.2 .12 0" quat="1 0 0 0"><joint name="car0_wheelfl_steer" type="hinge" axis="0 0 1" /><joint name="car0_wheelfl" type="hinge" axis="0 1 0" /><geom name="car0_wheelfl" type="cylinder" size=".06 .02" material="material_check" euler="1.571 0 0" /></body><body name="car0_wheelrl" pos="-0.2 .12 0" quat="1 0 0 0"><joint name="car0_wheelrl_steer" type="hinge" axis="0 0 1" /><joint name="car0_wheelrl" type="hinge" axis="0 1 0" /><geom name="car0_wheelrl" type="cylinder" size=".06 .02" material="material_check" euler="1.571 0 0" /></body><body name="car0_wheelfr" pos="0.2 -.12 0" quat="1 0 0 0"><joint name="car0_wheelfr_steer" type="hinge" axis="0 0 1" /><joint name="car0_wheelfr" type="hinge" axis="0 1 0" /><geom name="car0_wheelfr" type="cylinder" size=".06 .02" material="material_check" euler="1.571 0 0" /></body><body name="car0_wheelrr" pos="-0.2 -.12 0" quat="1 0 0 0"><joint name="car0_wheelrr_steer" type="hinge" axis="0 0 1" /><joint name="car0_wheelrr" type="hinge" axis="0 1 0" /><geom name="car0_wheelrr" type="cylinder" size=".06 .02" material="material_check" euler="1.571 0 0" /></body></body></worldbody><actuator /><sensor /></mujoco>