<mujoco><include file="../xml_models/scene.xml" /><worldbody><body name="virtcrazyflie_0" pos="1 1 1" quat="1 2 3 4"><inertial pos="0 0 0" diaginertia="1.4e-5 1.4e-5 2.17e-5" mass="0.028" /><joint name="virtcrazyflie_0" type="free" /><geom name="virtcrazyflie_0_body" type="mesh" mesh="drone_body" rgba="0.85 0.2 0.2 1.0" /><geom name="virtcrazyflie_0_4_motormounts" type="mesh" mesh="drone_4_motormounts" rgba="0.85 0.2 0.2 1.0" /><geom name="virtcrazyflie_0_4_motors" type="mesh" mesh="drone_4_motors" rgba="0.85 0.2 0.2 1.0" /><site name="virtcrazyflie_0_cog" pos="0 0 0" /><body name="virtcrazyflie_0_prop1"><joint name="virtcrazyflie_0_prop1" axis="0 0 1" pos="0.047 0.047 0.032" /><geom name="virtcrazyflie_0_prop1" type="mesh" mesh="drone_ccw_prop" mass="0.00001" pos="0.047 0.047 0.032" rgba="0.1 0.1 0.1 1.0" euler="0 0 -0.785" /></body><body name="virtcrazyflie_0_prop2"><joint name="virtcrazyflie_0_prop2" axis="0 0 1" pos="-0.047 -0.047 0.032" /><geom name="virtcrazyflie_0_prop2" type="mesh" mesh="drone_ccw_prop" mass="0.00001" pos="-0.047 -0.047 0.032" rgba="0.1 0.1 0.1 1.0" euler="0 0 -0.785" /></body><body name="virtcrazyflie_0_prop3"><joint name="virtcrazyflie_0_prop3" axis="0 0 1" pos="-0.047 0.047 0.032" /><geom name="virtcrazyflie_0_prop3" type="mesh" mesh="drone_cw_prop" mass="0.00001" pos="-0.047 0.047 0.032" rgba="0.1 0.1 0.1 1.0" euler="0 0 0.785" /></body><body name="virtcrazyflie_0_prop4"><joint name="virtcrazyflie_0_prop4" axis="0 0 1" pos="0.047 -0.047 0.032" /><geom name="virtcrazyflie_0_prop4" type="mesh" mesh="drone_cw_prop" mass="0.00001" pos="0.047 -0.047 0.032" rgba="0.1 0.1 0.1 1.0" euler="0 0 0.785" /></body></body><body name="virtbumblebee_hooked_0" pos="1 0 1" quat="1 0 0 0"><inertial pos="0 0 0" diaginertia="1.5e-3 1.45e-3 2.66e-3" mass="0.407" /><joint name="virtbumblebee_hooked_0" type="free" /><geom name="virtbumblebee_hooked_0_body" type="mesh" mesh="drone_body_large" rgba="0.85 0.2 0.2 1.0" /><site name="virtbumblebee_hooked_0_cog" pos="0 0 0" /><body name="virtbumblebee_hooked_0_rodbody" pos="0 0 0"><geom type="cylinder" fromto="0 0 0  0 0 -0.4" size="0.0025" mass="0.00" /><site name="virtbumblebee_hooked_0_rod_end" pos="0 0 -0.4" type="sphere" size="0.002" /><joint name="virtbumblebee_hooked_0_hook" axis="0 1 0" pos="0 0 0" damping="0.001" /><body name="virtbumblebee_hooked_0_hook" pos="0 0 -0.4" euler="0 3.141592 -1.57"><geom type="capsule" pos="0 0 0.02" size="0.002 0.02" mass="0.02" /><geom type="capsule" pos="0 0.01299 0.04750" euler="-1.04720 0 0" size="0.005 0.01800" mass="0.0001" /><geom type="capsule" pos="0 0.02598 0.07000" euler="0.00000 0 0" size="0.005 0.01800" mass="0.0001" /><geom type="capsule" pos="0 0.01299 0.09250" euler="1.04720 0 0" size="0.005 0.01800" mass="0.0001" /><geom type="capsule" pos="0 -0.01299 0.09250" euler="2.09440 0 0" size="0.005 0.01800" mass="0.0001" /></body></body><body name="virtbumblebee_hooked_0_prop1"><joint name="virtbumblebee_hooked_0_prop1" axis="0 0 1" pos="0.100 0.087 0.026" /><geom name="virtbumblebee_hooked_0_prop1" type="mesh" mesh="drone_ccw_prop_large" mass="0.00001" pos="0.100 0.087 0.026" rgba="0.1 0.02 0.5 1.0" /></body><body name="virtbumblebee_hooked_0_prop2"><joint name="virtbumblebee_hooked_0_prop2" axis="0 0 1" pos="-0.065 -0.087 0.026" /><geom name="virtbumblebee_hooked_0_prop2" type="mesh" mesh="drone_ccw_prop_large" mass="0.00001" pos="-0.065 -0.087 0.026" rgba="0.1 0.02 0.5 1.0" /></body><body name="virtbumblebee_hooked_0_prop3"><joint name="virtbumblebee_hooked_0_prop3" axis="0 0 1" pos="-0.065 0.087 0.026" /><geom name="virtbumblebee_hooked_0_prop3" type="mesh" mesh="drone_cw_prop_large" mass="0.00001" pos="-0.065 0.087 0.026" rgba="0.1 0.02 0.5 1.0" /></body><body name="virtbumblebee_hooked_0_prop4"><joint name="virtbumblebee_hooked_0_prop4" axis="0 0 1" pos="0.100 -0.087 0.026" /><geom name="virtbumblebee_hooked_0_prop4" type="mesh" mesh="drone_cw_prop_large" mass="0.00001" pos="0.100 -0.087 0.026" rgba="0.1 0.02 0.5 1.0" /></body></body><body name="realbumblebee_0" pos="1 .5 1" quat="1 0 0 0"><inertial pos="0 0 0" diaginertia="1.5e-3 1.45e-3 2.66e-3" mass="0.407" /><joint name="realbumblebee_0" type="free" /><geom name="realbumblebee_0_body" type="mesh" mesh="drone_body_large" rgba="0.2 0.2 0.85 1.0" /><site name="realbumblebee_0_cog" pos="0 0 0" /><body name="realbumblebee_0_prop1"><joint name="realbumblebee_0_prop1" axis="0 0 1" pos="0.100 0.087 0.026" /><geom name="realbumblebee_0_prop1" type="mesh" mesh="drone_ccw_prop_large" mass="0.00001" pos="0.100 0.087 0.026" rgba="0.1 0.02 0.5 1.0" /></body><body name="realbumblebee_0_prop2"><joint name="realbumblebee_0_prop2" axis="0 0 1" pos="-0.065 -0.087 0.026" /><geom name="realbumblebee_0_prop2" type="mesh" mesh="drone_ccw_prop_large" mass="0.00001" pos="-0.065 -0.087 0.026" rgba="0.1 0.02 0.5 1.0" /></body><body name="realbumblebee_0_prop3"><joint name="realbumblebee_0_prop3" axis="0 0 1" pos="-0.065 0.087 0.026" /><geom name="realbumblebee_0_prop3" type="mesh" mesh="drone_cw_prop_large" mass="0.00001" pos="-0.065 0.087 0.026" rgba="0.1 0.02 0.5 1.0" /></body><body name="realbumblebee_0_prop4"><joint name="realbumblebee_0_prop4" axis="0 0 1" pos="0.100 -0.087 0.026" /><geom name="realbumblebee_0_prop4" type="mesh" mesh="drone_cw_prop_large" mass="0.00001" pos="0.100 -0.087 0.026" rgba="0.1 0.02 0.5 1.0" /></body></body></worldbody><actuator><general site="virtcrazyflie_0_cog" gear=" 0 0 1 0 0 0" ctrllimited="true" ctrlrange="0 0.64" /><general site="virtcrazyflie_0_cog" gear=" 0 0 0 1 0 0" ctrllimited="true" ctrlrange="-0.01 0.01" /><general site="virtcrazyflie_0_cog" gear=" 0 0 0 0 1 0" ctrllimited="true" ctrlrange="-0.01 0.01" /><general site="virtcrazyflie_0_cog" gear=" 0 0 0 0 0 1" ctrllimited="true" ctrlrange="-0.01 0.01" /><general site="virtbumblebee_hooked_0_cog" gear=" 0 0 1 0 0 0" ctrllimited="true" ctrlrange="0 67.2" /><general site="virtbumblebee_hooked_0_cog" gear=" 0 0 0 1 0 0" ctrllimited="true" ctrlrange="-6 6" /><general site="virtbumblebee_hooked_0_cog" gear=" 0 0 0 0 1 0" ctrllimited="true" ctrlrange="-6 6" /><general site="virtbumblebee_hooked_0_cog" gear=" 0 0 0 0 0 1" ctrllimited="true" ctrlrange="-1.5 1.5" /><general site="realbumblebee_0_cog" gear=" 0 0 1 0 0 0" ctrllimited="true" ctrlrange="0 67.2" /><general site="realbumblebee_0_cog" gear=" 0 0 0 1 0 0" ctrllimited="true" ctrlrange="-6 6" /><general site="realbumblebee_0_cog" gear=" 0 0 0 0 1 0" ctrllimited="true" ctrlrange="-6 6" /><general site="realbumblebee_0_cog" gear=" 0 0 0 0 0 1" ctrllimited="true" ctrlrange="-1.5 1.5" /></actuator><sensor><gyro site="virtcrazyflie_0_cog" /><gyro site="virtbumblebee_hooked_0_cog" /><gyro site="realbumblebee_0_cog" /></sensor></mujoco>