<mujoco><include file="scene.xml" /><worldbody><body name="virtbumblebee_hooked_0" pos="0 0 1" quat="1 0 0 0"><inertial pos="0 0 0" diaginertia="1.5e-3 1.45e-3 2.66e-3" mass="0.407" /><joint name="virtbumblebee_hooked_0" type="free" /><geom name="virtbumblebee_hooked_0_body" pos="0.0132 0 0" type="mesh" quat="-0.7071067811865475 -0.0 0.0 0.7071067811865476" mesh="drone_body_large" rgba="0.85 0.2 0.2 1.0" /><site name="virtbumblebee_hooked_0_cog" pos="0 0 0" /><body name="virtbumblebee_hooked_0_rod" pos="0 0 0"><geom type="cylinder" fromto="0 0 0  0 0 -0.4" size="0.005" mass="0.00" /><site name="virtbumblebee_hooked_0_rod_end" pos="0 0 -0.4" type="sphere" size="0.002" /><joint name="virtbumblebee_hooked_0_hook_y" axis="0 1 0" pos="0 0 0" damping="0.001" /><body name="virtbumblebee_hooked_0_hook" pos="0 0 -0.4" euler="0 3.141592 -1.57"><geom type="capsule" pos="0 0 0.02" size="0.005 0.02" mass="0.02" /><geom type="capsule" pos="0 0.01299 0.0475" euler="-1.0472 0 0" size="0.005 0.018" mass="0.0001" /><geom type="capsule" pos="0 0.02598 0.07" euler="0 0 0" size="0.005 0.018" mass="0.0001" /><geom type="capsule" pos="0 0.01299 0.0925" euler="1.0472 0 0" size="0.005 0.018" mass="0.0001" /><geom type="capsule" pos="0 -0.01299 0.0925" euler="2.0944 0 0" size="0.005 0.018" mass="0.0001" /></body></body><body name="virtbumblebee_hooked_0_prop1"><joint name="virtbumblebee_hooked_0_prop1" axis="0 0 1" pos="-0.074 0.087 0.036" /><geom name="virtbumblebee_hooked_0_prop1" type="mesh" mesh="drone_ccw_prop_large" mass="0.00001" pos="-0.074 0.087 0.036" rgba="0.1 0.02 0.5 1.0" /></body><body name="virtbumblebee_hooked_0_prop2"><joint name="virtbumblebee_hooked_0_prop2" axis="0 0 1" pos="0.091 -0.087 0.036" /><geom name="virtbumblebee_hooked_0_prop2" type="mesh" mesh="drone_ccw_prop_large" mass="0.00001" pos="0.091 -0.087 0.036" rgba="0.1 0.02 0.5 1.0" /></body><body name="virtbumblebee_hooked_0_prop3"><joint name="virtbumblebee_hooked_0_prop3" axis="0 0 1" pos="0.091 0.087 0.036" /><geom name="virtbumblebee_hooked_0_prop3" type="mesh" mesh="drone_cw_prop_large" mass="0.00001" pos="0.091 0.087 0.036" rgba="0.1 0.02 0.5 1.0" /></body><body name="virtbumblebee_hooked_0_prop4"><joint name="virtbumblebee_hooked_0_prop4" axis="0 0 1" pos="-0.074 -0.087 0.036" /><geom name="virtbumblebee_hooked_0_prop4" type="mesh" mesh="drone_cw_prop_large" mass="0.00001" pos="-0.074 -0.087 0.036" rgba="0.1 0.02 0.5 1.0" /></body></body></worldbody><contact /><actuator><general site="virtbumblebee_hooked_0_cog" name="virtbumblebee_hooked_0_actr0" gear=" 0 0 1 0 0 0" ctrllimited="true" ctrlrange="0 67.2" /><general site="virtbumblebee_hooked_0_cog" name="virtbumblebee_hooked_0_actr1" gear=" 0 0 0 1 0 0" ctrllimited="true" ctrlrange="-6 6" /><general site="virtbumblebee_hooked_0_cog" name="virtbumblebee_hooked_0_actr2" gear=" 0 0 0 0 1 0" ctrllimited="true" ctrlrange="-6 6" /><general site="virtbumblebee_hooked_0_cog" name="virtbumblebee_hooked_0_actr3" gear=" 0 0 0 0 0 1" ctrllimited="true" ctrlrange="-1.5 1.5" /></actuator><sensor><gyro site="virtbumblebee_hooked_0_rod_end" name="virtbumblebee_hooked_0_hook_gyro" /><framequat objtype="site" objname="virtbumblebee_hooked_0_rod_end" name="virtbumblebee_hooked_0_hook_orimeter" /><gyro site="virtbumblebee_hooked_0_cog" name="virtbumblebee_hooked_0_gyro" /><velocimeter site="virtbumblebee_hooked_0_cog" name="virtbumblebee_hooked_0_velocimeter" /><accelerometer site="virtbumblebee_hooked_0_cog" name="virtbumblebee_hooked_0_accelerometer" /><framepos objtype="site" objname="virtbumblebee_hooked_0_cog" name="virtbumblebee_hooked_0_posimeter" /><framequat objtype="site" objname="virtbumblebee_hooked_0_cog" name="virtbumblebee_hooked_0_orimeter" /><frameangacc  objtype="site" objname="virtbumblebee_hooked_0_cog" name="virtbumblebee_hooked_0_ang_accelerometer" /></sensor></mujoco>