<mujoco>
    <include file="../xml_models/scene.xml" />
    <worldbody>
        <body name="virtdrone_hooked_0" pos="1 1 1" quat="1 0 0 0">
            <inertial pos="0 0 0" diaginertia="0.082 0.085 0.138" mass="4.34" />
            <joint name="virtdrone_hooked_0" type="free" />
            <body name="virtdrone_hooked_0_body" pos="0 0 0">
                <geom name="virtdrone_hooked_0_body" type="mesh" mesh="drone_body_large" rgba="0.85 0.2 0.2 1.0" mass="0.0001" />
                <geom name="virtdrone_hooked_0_4_motormounts" type="mesh" mesh="drone_4_motormounts_large" rgba="0.85 0.2 0.2 1.0" mass="0.0001" />
                <geom name="virtdrone_hooked_0_4_motors" type="mesh" mesh="drone_4_motors_large" rgba="0.85 0.2 0.2 1.0" mass="0.0001" />
            </body>
            <site name="virtdrone_hooked_0_cog" pos="0 0 0" />
            <body name="virtdrone_hooked_0_rodbody" pos="0 0 0">
                <geom type="cylinder" fromto="0 0 0  0 0 -0.4" size="0.002" mass="0.00" />
                <site name="virtdrone_hooked_0_rod_end" pos="0 0 -0.4" type="sphere" size="0.002" />
                <joint name="virtdrone_hooked_0_hook" axis="0 1 0" pos="0 0 0" damping="0.001" />
                <body name="virtdrone_hooked_0_hook" pos="0 0 -0.4" euler="0 3.141592 -1.57">
                    <geom type="capsule" pos="0 0 0.02" size="0.002 0.02" mass="0.05" />
                    <geom type="capsule" pos="0 0.01299 0.04750" euler="-1.04720 0 0" size="0.0035 0.01800" mass="0.0001" />
                    <geom type="capsule" pos="0 0.02598 0.07000" euler="0.00000 0 0" size="0.0035 0.01800" mass="0.0001" />
                    <geom type="capsule" pos="0 0.01299 0.09250" euler="1.04720 0 0" size="0.0035 0.01800" mass="0.0001" />
                    <geom type="capsule" pos="0 -0.01299 0.09250" euler="2.09440 0 0" size="0.0035 0.01800" mass="0.0001" />
                </body>
            </body>
            <body name="virtdrone_hooked_0_prop1">
                <joint name="virtdrone_hooked_0_prop1" axis="0 0 1" pos="0.157 0.157 0.107" />
                <geom name="virtdrone_hooked_0_prop1" type="mesh" mesh="drone_ccw_prop_large" mass="0.00001" pos="0.157 0.157 0.107" rgba="0.1 0.1 0.1 1.0" euler="0 0 -0.785" />
            </body>
            <body name="virtdrone_hooked_0_prop2">
                <joint name="virtdrone_hooked_0_prop2" axis="0 0 1" pos="-0.157 -0.157 0.107" />
                <geom name="virtdrone_hooked_0_prop2" type="mesh" mesh="drone_ccw_prop_large" mass="0.00001" pos="-0.157 -0.157 0.107" rgba="0.1 0.1 0.1 1.0" euler="0 0 -0.785" />
            </body>
            <body name="virtdrone_hooked_0_prop3">
                <joint name="virtdrone_hooked_0_prop3" axis="0 0 1" pos="-0.157 0.157 0.107" />
                <geom name="virtdrone_hooked_0_prop3" type="mesh" mesh="drone_cw_prop_large" mass="0.00001" pos="-0.157 0.157 0.107" rgba="0.1 0.1 0.1 1.0" euler="0 0 0.785" />
            </body>
            <body name="virtdrone_hooked_0_prop4">
                <joint name="virtdrone_hooked_0_prop4" axis="0 0 1" pos="0.157 -0.157 0.107" />
                <geom name="virtdrone_hooked_0_prop4" type="mesh" mesh="drone_cw_prop_large" mass="0.00001" pos="0.157 -0.157 0.107" rgba="0.1 0.1 0.1 1.0" euler="0 0 0.785" />
            </body>
        </body>
        <body name="load_0" pos="0 0 0" quat="1 0 0 0">
            <geom type="box" size=".15 .15 .1" mass=".15" pos="0 0 .1" rgba="0.7 0.7 0.1 1.0" />
            <joint type="free" />
            <body name="load_0_hook" pos="0 0 0.2">
                <geom type="capsule" pos="0 0 0.02" size="0.002 0.02" mass="0.0001" />
                <geom type="capsule" pos="0 0.01173 0.04565" euler="-1.12200 0 0" size="0.004 0.01562" mass="0.0001" />
                <geom type="capsule" pos="0 0.01061 0.04439" euler="-1.17810 0 0" size="0.004 0.01378" mass="0.0001" />
                <geom type="capsule" pos="0 0.02561 0.05939" euler="-0.39270 0 0" size="0.004 0.01378" mass="0.0001" />
                <geom type="capsule" pos="0 0.02561 0.08061" euler="0.39270 0 0" size="0.004 0.01378" mass="0.0001" />
                <geom type="capsule" pos="0 0.01061 0.09561" euler="1.17810 0 0" size="0.004 0.01378" mass="0.0001" />
                <geom type="capsule" pos="0 -0.01061 0.09561" euler="1.96350 0 0" size="0.004 0.01378" mass="0.0001" />
                <geom type="capsule" pos="0 -0.02561 0.08061" euler="2.74889 0 0" size="0.004 0.01378" mass="0.0001" />
            </body>
        </body>
        <body name="load_1" pos="-.6 .6 .1" quat="1 0 0 0">
            <geom type="box" size=".1 .1 .1" mass=".05" pos="0 0 .1" rgba="0.1 0.9 0.1 1.0" />
            <joint type="free" />
            <body name="load_1_hook" pos="0 0 0.2">
                <geom type="capsule" pos="0 0 0.02" size="0.002 0.02" mass="0.0001" />
                <geom type="capsule" pos="0 0.01173 0.04565" euler="-1.12200 0 0" size="0.004 0.01562" mass="0.0001" />
                <geom type="capsule" pos="0 0.01061 0.04439" euler="-1.17810 0 0" size="0.004 0.01378" mass="0.0001" />
                <geom type="capsule" pos="0 0.02561 0.05939" euler="-0.39270 0 0" size="0.004 0.01378" mass="0.0001" />
                <geom type="capsule" pos="0 0.02561 0.08061" euler="0.39270 0 0" size="0.004 0.01378" mass="0.0001" />
                <geom type="capsule" pos="0 0.01061 0.09561" euler="1.17810 0 0" size="0.004 0.01378" mass="0.0001" />
                <geom type="capsule" pos="0 -0.01061 0.09561" euler="1.96350 0 0" size="0.004 0.01378" mass="0.0001" />
                <geom type="capsule" pos="0 -0.02561 0.08061" euler="2.74889 0 0" size="0.004 0.01378" mass="0.0001" />
            </body>
        </body>
        <body name="load_2" pos="-.3 -.6 .1" quat="1 0 0 0">
            <geom type="box" size=".1 .1 .15" mass=".1" pos="0 0 .15" rgba="0.1 0.1 0.9 1.0" />
            <joint type="free" />
            <body name="load_2_hook" pos="0 0 0.3">
                <geom type="capsule" pos="0 0 0.02" size="0.002 0.02" mass="0.0001" />
                <geom type="capsule" pos="0 0.01173 0.04565" euler="-1.12200 0 0" size="0.004 0.01562" mass="0.0001" />
                <geom type="capsule" pos="0 0.01061 0.04439" euler="-1.17810 0 0" size="0.004 0.01378" mass="0.0001" />
                <geom type="capsule" pos="0 0.02561 0.05939" euler="-0.39270 0 0" size="0.004 0.01378" mass="0.0001" />
                <geom type="capsule" pos="0 0.02561 0.08061" euler="0.39270 0 0" size="0.004 0.01378" mass="0.0001" />
                <geom type="capsule" pos="0 0.01061 0.09561" euler="1.17810 0 0" size="0.004 0.01378" mass="0.0001" />
                <geom type="capsule" pos="0 -0.01061 0.09561" euler="1.96350 0 0" size="0.004 0.01378" mass="0.0001" />
                <geom type="capsule" pos="0 -0.02561 0.08061" euler="2.74889 0 0" size="0.004 0.01378" mass="0.0001" />
            </body>
        </body>


        <body name="load_target0" pos="2.2 1 0.001">
            <geom type="box" size=".15 .15 .0009" rgba="0.7 0.7 0.1 1.0"/>
        </body>
        <body name="load_target1" pos="1.8 1 0.001">
            <geom type="box" size=".1 .1 .0009" rgba="0.1 0.9 0.1 1.0"/>
        </body>
        <body name="load_target2" pos="1.4 1 0.001">
            <geom type="box" size=".1 .1 .0009" rgba="0.1 0.1 0.9 1.0"/>
        </body>
        
    </worldbody>
    <actuator>
        <general site="virtdrone_hooked_0_cog" gear=" 0 0 1 0 0 0" ctrllimited="true" ctrlrange="0 67.2" />
        <general site="virtdrone_hooked_0_cog" gear=" 0 0 0 1 0 0" ctrllimited="true" ctrlrange="-6 6" />
        <general site="virtdrone_hooked_0_cog" gear=" 0 0 0 0 1 0" ctrllimited="true" ctrlrange="-6 6" />
        <general site="virtdrone_hooked_0_cog" gear=" 0 0 0 0 0 1" ctrllimited="true" ctrlrange="-1.5 1.5" />
    </actuator>
    <sensor>
        <gyro site="virtdrone_hooked_0_cog" />
    </sensor>
</mujoco>