<mujoco model="hook_scenario">
  <compiler angle="radian" meshdir=""/>
  <option timestep="0.001"/>
  <visual>
    <quality shadowsize="0"/>
  </visual>

  <asset>
    <mesh file="../3d_models/cf2_assembly.stl" name="drone" smoothnormal="true" scale="5 5 5"/>
    <!--<mesh file="hook.stl" name="hook" smoothnormal="true" scale=".005 .005 .005"/>-->
    <texture type="skybox" builtin="gradient" rgb1=".3 .5 .7" rgb2="0 0 0" width="512" height="512"/>
    <texture name="grid" type="2d" builtin="checker" width="512" height="512" rgb1=".1 .2 .3" rgb2=".2 .3 .4"/>
    <material name="grid" texture="grid" texrepeat="1 1" texuniform="true" reflectance=".0"/>
  </asset>

  <worldbody>
    <camera pos="2.867 -5.173 1.776" xyaxes="0.875 0.485 0.000 -0.139 0.252 0.958"/>
    <geom size="50 50 .05" type="plane" material="grid" condim="3"/>
    <light dir=".2 1 -.4" diffuse="1 1 1" specular="0.6 0.9 0.6" pos="-2 -10 6" cutoff="70"/>
    <light dir="-.2 1 -.4" diffuse="1 1 1" specular="0.6 0.9 0.6" pos="2 -10 6" cutoff="70"/>

    <body name="drone1" pos="-0.69 0 1.5">
        <inertial pos="0 0 0" diaginertia="0.082 0.085 0.138" mass="4.34"/>
        <joint type="free" name="drone0_jnt"/>
        <geom name="drone1" type="mesh" pos="0 0 -0.05" mesh="drone"/>
        <site name="drone1_cog" pos="0 0 0"/>
        <body name="rod1" pos="0 0 0" euler="0 0 0">
            <geom type="cylinder" fromto="0 0 0  0 0 -0.4" size="0.002" mass="0.00"/>
            <site name="rod_end1" pos="0 0 -0.4" type="sphere" size="0.002"/>
            <joint axis="0 1 0" pos="0 0 0" damping="0.001"/>
            <body name="hook1" pos="0 0 -0.4" euler="0 3.141592 -1.57">
            <geom type="capsule" pos="0 0 0.02" size="0.002 0.02" mass="0.05"/>

            <geom type="capsule" pos="0 0.01299 0.04750" euler="-1.04720 0 0" size="0.0035 0.01800" mass="0.0001"/>
            <geom type="capsule" pos="0 0.02598 0.07000" euler="0.00000 0 0" size="0.0035 0.01800" mass="0.0001"/>
            <geom type="capsule" pos="0 0.01299 0.09250" euler="1.04720 0 0" size="0.0035 0.01800" mass="0.0001"/>
            <geom type="capsule" pos="0 -0.01299 0.09250" euler="2.09440 0 0" size="0.0035 0.01800" mass="0.0001"/>

            </body>
        </body>
    </body>
    <body name="drone0" pos="0.69 0 1.5">
        <inertial pos="0 0 0" diaginertia="0.082 0.085 0.138" mass="4.34"/>
        <joint type="free" name="drone1_jnt"/>
        <geom name="drone0" type="mesh" pos="0 0 -0.05" mesh="drone"/>
        <site name="drone0_cog" pos="0 0 0"/>
        <body name="rod0" pos="0 0 0" euler="0 0 0">
            <geom type="cylinder" fromto="0 0 0  0 0 -0.4" size="0.002" mass="0.00"/>
            <site name="rod_end0" pos="0 0 -0.4" type="sphere" size="0.002"/>
            <joint axis="0 1 0" pos="0 0 0" damping="0.001"/>
            <body name="hook0" pos="0 0 -0.4" euler="0 3.141592 -1.57">
            <geom type="capsule" pos="0 0 0.02" size="0.002 0.02" mass="0.05"/>

            <geom type="capsule" pos="0 0.01299 0.04750" euler="-1.04720 0 0" size="0.0035 0.01800" mass="0.0001"/>
            <geom type="capsule" pos="0 0.02598 0.07000" euler="0.00000 0 0" size="0.0035 0.01800" mass="0.0001"/>
            <geom type="capsule" pos="0 0.01299 0.09250" euler="1.04720 0 0" size="0.0035 0.01800" mass="0.0001"/>
            <geom type="capsule" pos="0 -0.01299 0.09250" euler="2.09440 0 0" size="0.0035 0.01800" mass="0.0001"/>

            </body>
        </body>
            
    </body>

      <body name="load2" pos="-0.6 0.6 0.1">
        <geom type="box" size=".1 .1 .1" mass="0.05" rgba="0 1 0 1"/>
        <joint type="free"/>
        <body name="hookload2" pos="0 0 .1">
            <geom type="capsule" pos="0 0 0.02" size="0.002 0.02" mass="0.0001"/>

            <geom type="capsule" pos="0 0.01173 0.04565" euler="-1.12200 0 0" size="0.004 0.01562" mass="0.0001"/>
            <geom type="capsule" pos="0 0.01061 0.04439" euler="-1.17810 0 0" size="0.004 0.01378" mass="0.0001"/>
            <geom type="capsule" pos="0 0.02561 0.05939" euler="-0.39270 0 0" size="0.004 0.01378" mass="0.0001"/>
            <geom type="capsule" pos="0 0.02561 0.08061" euler="0.39270 0 0" size="0.004 0.01378" mass="0.0001"/>
            <geom type="capsule" pos="0 0.01061 0.09561" euler="1.17810 0 0" size="0.004 0.01378" mass="0.0001"/>
            <geom type="capsule" pos="0 -0.01061 0.09561" euler="1.96350 0 0" size="0.004 0.01378" mass="0.0001"/>
            <geom type="capsule" pos="0 -0.02561 0.08061" euler="2.74889 0 0" size="0.004 0.01378" mass="0.0001"/>

        </body>
    </body>

    <body name="load1" pos="0 0 0.1">
        <geom type="box" size=".15 .15 .1" mass="0.15" rgba="1 0 0 1"/>
        <joint type="free"/>
        <body name="hookload1" pos="0 0 .1">
            <geom type="capsule" pos="0 0 0.02" size="0.002 0.02" mass="0.0001"/>

            <geom type="capsule" pos="0 0.01173 0.04565" euler="-1.12200 0 0" size="0.004 0.01562" mass="0.0001"/>
            <geom type="capsule" pos="0 0.01061 0.04439" euler="-1.17810 0 0" size="0.004 0.01378" mass="0.0001"/>
            <geom type="capsule" pos="0 0.02561 0.05939" euler="-0.39270 0 0" size="0.004 0.01378" mass="0.0001"/>
            <geom type="capsule" pos="0 0.02561 0.08061" euler="0.39270 0 0" size="0.004 0.01378" mass="0.0001"/>
            <geom type="capsule" pos="0 0.01061 0.09561" euler="1.17810 0 0" size="0.004 0.01378" mass="0.0001"/>
            <geom type="capsule" pos="0 -0.01061 0.09561" euler="1.96350 0 0" size="0.004 0.01378" mass="0.0001"/>
            <geom type="capsule" pos="0 -0.02561 0.08061" euler="2.74889 0 0" size="0.004 0.01378" mass="0.0001"/>

        </body>
    </body>

      <body name="load3" pos="-0.3 -0.6 0.1">
        <geom type="box" size=".1 .1 .15" mass="0.1" rgba="0 0 1 1"/>
        <joint type="free"/>
        <body name="hookload3" pos="0 0 .15">
            <geom type="capsule" pos="0 0 0.02" size="0.002 0.02" mass="0.0001"/>

            <geom type="capsule" pos="0 0.01173 0.04565" euler="-1.12200 0 0" size="0.004 0.01562" mass="0.0001"/>
            <geom type="capsule" pos="0 0.01061 0.04439" euler="-1.17810 0 0" size="0.004 0.01378" mass="0.0001"/>
            <geom type="capsule" pos="0 0.02561 0.05939" euler="-0.39270 0 0" size="0.004 0.01378" mass="0.0001"/>
            <geom type="capsule" pos="0 0.02561 0.08061" euler="0.39270 0 0" size="0.004 0.01378" mass="0.0001"/>
            <geom type="capsule" pos="0 0.01061 0.09561" euler="1.17810 0 0" size="0.004 0.01378" mass="0.0001"/>
            <geom type="capsule" pos="0 -0.01061 0.09561" euler="1.96350 0 0" size="0.004 0.01378" mass="0.0001"/>
            <geom type="capsule" pos="0 -0.02561 0.08061" euler="2.74889 0 0" size="0.004 0.01378" mass="0.0001"/>

        </body>
    </body>


      <body name="load_target1" pos="2.2 1 0.0005">
              <geom type="box" size=".15 .15 .0005" rgba="1 0 0 1"/>
      </body>
            <body name="load_target2" pos="1.8 1 0.0005">
              <geom type="box" size=".1 .1 .0005" rgba="0 1 0 1"/>
      </body>
            <body name="load_target3" pos="1.4 1 0.0005">
              <geom type="box" size=".1 .1 .0005" rgba="0 0 1 1"/>
      </body>

  </worldbody>

  <actuator>
      <general site="drone0_cog" gear=" 0 0 1 0 0 0" ctrllimited="true" ctrlrange="0 67.2"/>
      <general site="drone0_cog" gear=" 0 0 0 1 0 0" ctrllimited="true" ctrlrange="-6 6"/>
      <general site="drone0_cog" gear=" 0 0 0 0 1 0" ctrllimited="true" ctrlrange="-6 6"/>
      <general site="drone0_cog" gear=" 0 0 0 0 0 1" ctrllimited="true" ctrlrange="-1.5 1.5"/>
      <general site="drone1_cog" gear=" 0 0 1 0 0 0" ctrllimited="true" ctrlrange="0 67.2"/>
      <general site="drone1_cog" gear=" 0 0 0 1 0 0" ctrllimited="true" ctrlrange="-6 6"/>
      <general site="drone1_cog" gear=" 0 0 0 0 1 0" ctrllimited="true" ctrlrange="-6 6"/>
      <general site="drone1_cog" gear=" 0 0 0 0 0 1" ctrllimited="true" ctrlrange="-1.5 1.5"/>
  </actuator>
  <sensor>
      <gyro name="drone0" site="drone0_cog"/>
      <gyro name="drone1" site="drone1_cog"/>
  </sensor>
</mujoco>