<mujoco>
	<include file="scene_base.xml" />
	<worldbody>
		<body name="Bicycle_0" pos="0 0.2 0.06">
			<inertial pos="0 0 0" diaginertia=".01 .01 .01" mass="1.0" />
			<joint type="free" name="Bicycle_0" />
			<site name="Bicycle_0_cog" pos="0 0 0" />
			<geom name="Bicycle_0_crossbar" type="box" size="0.06 0.02 0.02" pos="0. 0. 0." rgba="0.2 0.2 0.8 1.0" />
			<body name="Bicycle_0_wheelf">
				<joint name="Bicycle_0_wheelf" type="hinge" pos="0.1 0 0" axis="0 1 0" frictionloss="0.001" damping="0.00001" armature="0.01" />
				<geom name="Bicycle_0_wheelf" type="cylinder" size="0.04 0.015" pos="0.1 0 0" euler="1.571 0 0" material="material_check" />
			</body>
			<body name="Bicycle_0_wheelr">
				<joint name="Bicycle_0_wheelr" type="hinge" pos="-0.1 0 0" axis="0 1 0" frictionloss="0.001" damping="0.00001" armature="0.01" />
				<geom name="Bicycle_0_wheelr" type="cylinder" size="0.04 0.015" pos="-0.1 0 0" euler="1.571 0 0" material="material_check" />
			</body>
		</body>
		<body name="Bicycle_1" pos="0 1 0" quat="1 0 0 0">
			<inertial pos="0 0 0" diaginertia=".01 .01 .01" mass="1.0" />
			<joint name="Bicycle_1" type="free" />
			<site name="Bicycle_1_cog" pos="0 0 0" />
			<geom name="Bicycle_1_crossbar" type="box" size=".06 .015 .02" pos="0 0 0" rgba="0.5 0.5 0.5 1" />
			<body name="Bicycle_1_wheelf">
				<joint name="Bicycle_1_wheelf" type="hinge" pos="0.1 0 0" axis="0 1 0" frictionloss="0.001" damping="0.00001" armature="0.01" />
				<geom name="Bicycle_1_wheelf" type="cylinder" size="0.04 0.015" pos="0.1 0 0" euler="1.571 0 0" material="material_check" />
			</body>
			<body name="Bicycle_1_wheelr">
				<joint name="Bicycle_1_wheelr" type="hinge" pos="-0.1 0 0" axis="0 1 0" frictionloss="0.001" damping="0.00001" armature="0.01" />
				<geom name="Bicycle_1_wheelr" type="cylinder" size="0.04 0.015" pos="-0.1 0 0" euler="1.571 0 0" material="material_check" />
			</body>
		</body>
		<body name="Bicycle_2" pos="0 -1 0" quat="1 0 0 0">
			<inertial pos="0 0 0" diaginertia=".01 .01 .01" mass="1.0" />
			<joint name="Bicycle_2" type="free" />
			<site name="Bicycle_2_cog" pos="0 0 0" />
			<geom name="Bicycle_2_crossbar" type="box" size=".06 .015 .02" pos="0 0 0" rgba="0.5 0.5 0.5 1" />
			<body name="Bicycle_2_wheelf">
				<joint name="Bicycle_2_wheelf" type="hinge" pos="0.1 0 0" axis="0 1 0" frictionloss="0.001" damping="0.00001" armature="0.01" />
				<geom name="Bicycle_2_wheelf" type="cylinder" size="0.04 0.015" pos="0.1 0 0" euler="1.571 0 0" material="material_check" />
			</body>
			<body name="Bicycle_2_wheelr">
				<joint name="Bicycle_2_wheelr" type="hinge" pos="-0.1 0 0" axis="0 1 0" frictionloss="0.001" damping="0.00001" armature="0.01" />
				<geom name="Bicycle_2_wheelr" type="cylinder" size="0.04 0.015" pos="-0.1 0 0" euler="1.571 0 0" material="material_check" />
			</body>
		</body>
		<body name="Crazyflie_0" pos="1 0 1.5" quat="1 0 0 0">
			<geom name="Crazyflie_0_body" type="mesh" mesh="crazyflie_body" rgba="0.5 0.5 0.5 1" />
			<geom name="Crazyflie_0_4_motormounts" type="mesh" mesh="crazyflie_4_motormounts" rgba="0.5 0.5 0.5 1" />
			<geom name="Crazyflie_0_4_motors" type="mesh" mesh="crazyflie_4_motors" rgba="0.5 0.5 0.5 1" />
			<inertial pos="0.0 0.0 0.0" diaginertia="1.4e-5 1.4e-5 2.17e-5" mass="0.028" />
			<joint name="Crazyflie_0" type="free" />
			<site name="Crazyflie_0_cog" pos="0 0 0" size="0.005" />
			<body name="Crazyflie_0_prop0">
				<joint name="Crazyflie_0_prop0" axis="0 0 1" pos="0.03275 -0.03275 0.0223" />
				<geom name="Crazyflie_0_prop0" type="mesh" mesh="crazyflie_ccw_prop" mass="0.00001" pos="0.03275 -0.03275 0.0223" rgba="0.1 0.1 0.1 1.0" />
			</body>
			<site name="Crazyflie_0_prop0" pos="0.03275 -0.03275 0.0223" size="0.0001" />
			<body name="Crazyflie_0_prop1">
				<joint name="Crazyflie_0_prop1" axis="0 0 1" pos="-0.03275 -0.03275 0.0223" />
				<geom name="Crazyflie_0_prop1" type="mesh" mesh="crazyflie_cw_prop" mass="0.00001" pos="-0.03275 -0.03275 0.0223" rgba="0.1 0.1 0.1 1.0" />
			</body>
			<site name="Crazyflie_0_prop1" pos="-0.03275 -0.03275 0.0223" size="0.0001" />
			<body name="Crazyflie_0_prop2">
				<joint name="Crazyflie_0_prop2" axis="0 0 1" pos="-0.03275 0.03275 0.0223" />
				<geom name="Crazyflie_0_prop2" type="mesh" mesh="crazyflie_ccw_prop" mass="0.00001" pos="-0.03275 0.03275 0.0223" rgba="0.1 0.1 0.1 1.0" />
			</body>
			<site name="Crazyflie_0_prop2" pos="-0.03275 0.03275 0.0223" size="0.0001" />
			<body name="Crazyflie_0_prop3">
				<joint name="Crazyflie_0_prop3" axis="0 0 1" pos="0.03275 0.03275 0.0223" />
				<geom name="Crazyflie_0_prop3" type="mesh" mesh="crazyflie_cw_prop" mass="0.00001" pos="0.03275 0.03275 0.0223" rgba="0.1 0.1 0.1 1.0" />
			</body>
			<site name="Crazyflie_0_prop3" pos="0.03275 0.03275 0.0223" size="0.0001" />
		</body>
		<body name="Bumblebee_0" pos="-1 0 0.5" quat="1 0 0 0">
			<geom name="Bumblebee_0_body" pos="0.0132 0 0" type="mesh" quat="-0.7071067811865475 -0.0 0.0 0.7071067811865476" mesh="bumblebee_body" rgba="0.5 0.5 0.5 1" />
			<inertial pos="0.0085 0.0 0.0" diaginertia="1.5e-3 1.45e-3 2.66e-3" mass="0.605" />
			<joint name="Bumblebee_0" type="free" />
			<site name="Bumblebee_0_cog" pos="0 0 0" size="0.005" />
			<body name="Bumblebee_0_prop0">
				<joint name="Bumblebee_0_prop0" axis="0 0 1" pos="0.091 -0.087 0.036" />
				<geom name="Bumblebee_0_prop0" type="mesh" mesh="bumblebee_ccw_prop" mass="0.00001" pos="0.091 -0.087 0.036" rgba="0.1 0.02 0.5 1.0" />
			</body>
			<site name="Bumblebee_0_prop0" pos="0.091 -0.087 0.036" size="0.0001" />
			<body name="Bumblebee_0_prop1">
				<joint name="Bumblebee_0_prop1" axis="0 0 1" pos="-0.074 -0.087 0.036" />
				<geom name="Bumblebee_0_prop1" type="mesh" mesh="bumblebee_cw_prop" mass="0.00001" pos="-0.074 -0.087 0.036" rgba="0.1 0.02 0.5 1.0" />
			</body>
			<site name="Bumblebee_0_prop1" pos="-0.074 -0.087 0.036" size="0.0001" />
			<body name="Bumblebee_0_prop2">
				<joint name="Bumblebee_0_prop2" axis="0 0 1" pos="-0.074 0.087 0.036" />
				<geom name="Bumblebee_0_prop2" type="mesh" mesh="bumblebee_ccw_prop" mass="0.00001" pos="-0.074 0.087 0.036" rgba="0.1 0.02 0.5 1.0" />
			</body>
			<site name="Bumblebee_0_prop2" pos="-0.074 0.087 0.036" size="0.0001" />
			<body name="Bumblebee_0_prop3">
				<joint name="Bumblebee_0_prop3" axis="0 0 1" pos="0.091 0.087 0.036" />
				<geom name="Bumblebee_0_prop3" type="mesh" mesh="bumblebee_cw_prop" mass="0.00001" pos="0.091 0.087 0.036" rgba="0.1 0.02 0.5 1.0" />
			</body>
			<site name="Bumblebee_0_prop3" pos="0.091 0.087 0.036" size="0.0001" />
		</body>
	</worldbody>
	<actuator>
		<motor name="Bicycle_0_actr" joint="Bicycle_0_wheelr" />
		<motor name="Bicycle_1_actr" joint="Bicycle_1_wheelr" />
		<motor name="Bicycle_2_actr" joint="Bicycle_2_wheelr" />
		<general site="Crazyflie_0_prop0" name="Crazyflie_0_actr0" gear="0 0 1 0 0 0.02514" ctrllimited="true" ctrlrange="0 0.16" />
		<general site="Crazyflie_0_prop1" name="Crazyflie_0_actr1" gear="0 0 1 0 0 -0.02514" ctrllimited="true" ctrlrange="0 0.16" />
		<general site="Crazyflie_0_prop2" name="Crazyflie_0_actr2" gear="0 0 1 0 0 0.02514" ctrllimited="true" ctrlrange="0 0.16" />
		<general site="Crazyflie_0_prop3" name="Crazyflie_0_actr3" gear="0 0 1 0 0 -0.02514" ctrllimited="true" ctrlrange="0 0.16" />
		<general site="Bumblebee_0_prop0" name="Bumblebee_0_actr0" gear="0 0 1 0 0 0.5954" ctrllimited="true" ctrlrange="0 15" />
		<general site="Bumblebee_0_prop1" name="Bumblebee_0_actr1" gear="0 0 1 0 0 -0.5954" ctrllimited="true" ctrlrange="0 15" />
		<general site="Bumblebee_0_prop2" name="Bumblebee_0_actr2" gear="0 0 1 0 0 0.5954" ctrllimited="true" ctrlrange="0 15" />
		<general site="Bumblebee_0_prop3" name="Bumblebee_0_actr3" gear="0 0 1 0 0 -0.5954" ctrllimited="true" ctrlrange="0 15" />
	</actuator>
	<sensor>
		<velocimeter site="Bicycle_0_cog" name="Bicycle_0_velocimeter" />
		<velocimeter site="Bicycle_1_cog" name="Bicycle_1_velocimeter" />
		<velocimeter site="Bicycle_2_cog" name="Bicycle_2_velocimeter" />
		<gyro site="Crazyflie_0_cog" name="Crazyflie_0_gyro" />
		<framelinvel objtype="site" objname="Crazyflie_0_cog" name="Crazyflie_0_velocimeter" />
		<accelerometer site="Crazyflie_0_cog" name="Crazyflie_0_accelerometer" />
		<framepos objtype="site" objname="Crazyflie_0_cog" name="Crazyflie_0_posimeter" />
		<framequat objtype="site" objname="Crazyflie_0_cog" name="Crazyflie_0_orimeter" />
		<frameangacc objtype="site" objname="Crazyflie_0_cog" name="Crazyflie_0_ang_accelerometer" />
		<gyro site="Bumblebee_0_cog" name="Bumblebee_0_gyro" />
		<framelinvel objtype="site" objname="Bumblebee_0_cog" name="Bumblebee_0_velocimeter" />
		<accelerometer site="Bumblebee_0_cog" name="Bumblebee_0_accelerometer" />
		<framepos objtype="site" objname="Bumblebee_0_cog" name="Bumblebee_0_posimeter" />
		<framequat objtype="site" objname="Bumblebee_0_cog" name="Bumblebee_0_orimeter" />
		<frameangacc objtype="site" objname="Bumblebee_0_cog" name="Bumblebee_0_ang_accelerometer" />
	</sensor>
</mujoco>