<mujoco model="empty_checkerboard">
	<include file="common_assets.xml" />
	<asset>
		<texture name="grid" type="2d" builtin="checker" width="100" height="100" rgb1=".1 .2 .3" rgb2=".25 .35 .45" />
		<material name="grid" texture="grid" texrepeat="1 1" texuniform="true" reflectance=".05" />
	</asset>
	<worldbody>
		<light dir="0 -0.3 -1" diffuse=".9 .9 .9" specular="0.6 0.9 0.6" pos="1 1 15" cutoff="70" />
		<light dir="-.2 1 -.4" diffuse=".9 .9 .9" specular="0.6 0.9 0.6" pos="2 -5 6" cutoff="70" />
		<light dir="-1.0 -1.0 -.4" diffuse=".9 .9 .9" specular="0.6 0.9 0.6" pos="10 10 6" directional="true" cutoff="70" />
		<camera pos="2.867 -5.173 1.776" xyaxes="0.875 0.485 0.000 -0.139 0.252 0.958" />
		<geom size="20 20 .05" type="plane" material="grid" condim="3" />
		<body name="MocapCrazyflie_0" pos="0 0 0" quat="1 0 0 0" mocap="true">
			<geom name="MocapCrazyflie_0_body" type="mesh" mesh="crazyflie_body" rgba="0.5 0.5 0.5 1" />
			<geom name="MocapCrazyflie_0_4_motormounts" type="mesh" mesh="crazyflie_4_motormounts" rgba="0.5 0.5 0.5 1" />
			<geom name="MocapCrazyflie_0_4_motors" type="mesh" mesh="crazyflie_4_motors" rgba="0.5 0.5 0.5 1" />
			<body name="MocapCrazyflie_0_prop0">
				<joint name="MocapCrazyflie_0_prop0" axis="0 0 1" pos="0.03275 -0.03275 0.0223" />
				<geom name="MocapCrazyflie_0_prop0" type="mesh" mesh="crazyflie_ccw_prop" pos="0.03275 -0.03275 0.0223" rgba="0.1 0.1 0.1 1.0" />
			</body>
			<body name="MocapCrazyflie_0_prop1">
				<joint name="MocapCrazyflie_0_prop1" axis="0 0 1" pos="-0.03275 -0.03275 0.0223" />
				<geom name="MocapCrazyflie_0_prop1" type="mesh" mesh="crazyflie_cw_prop" pos="-0.03275 -0.03275 0.0223" rgba="0.1 0.1 0.1 1.0" />
			</body>
			<body name="MocapCrazyflie_0_prop2">
				<joint name="MocapCrazyflie_0_prop2" axis="0 0 1" pos="-0.03275 0.03275 0.0223" />
				<geom name="MocapCrazyflie_0_prop2" type="mesh" mesh="crazyflie_ccw_prop" pos="-0.03275 0.03275 0.0223" rgba="0.1 0.1 0.1 1.0" />
			</body>
			<body name="MocapCrazyflie_0_prop3">
				<joint name="MocapCrazyflie_0_prop3" axis="0 0 1" pos="0.03275 0.03275 0.0223" />
				<geom name="MocapCrazyflie_0_prop3" type="mesh" mesh="crazyflie_cw_prop" pos="0.03275 0.03275 0.0223" rgba="0.1 0.1 0.1 1.0" />
			</body>
		</body>
	</worldbody>
</mujoco>